Workbook
Name _: #REF!
Name __10: #REF!
Name __11: #REF!
Name __6: #REF!
Name __7: #REF!
Name __8: #REF!
Name __9: #REF!
Name __C: #REF!
Name _1: #N/A
Name _10: #N/A
Name _10A_: #REF!
Name _10A_1: #REF!
Name _10A_10: #REF!
Name _10A_11: #REF!
Name _10A_12: #REF!
Name _10A_13: #REF!
Name _10A_14: #REF!
Name _10A_15: #REF!
Name _10A_16: #REF!
Name _10A_17: #REF!
Name _10A_18: #REF!
Name _10A_19: #REF!
Name _10A_2: #REF!
Name _10A_20: #REF!
Name _10A_21: #REF!
Name _10A_22: #REF!
Name _10A_23: #REF!
Name _10A_24: #REF!
Name _10A_25: #REF!
Name _10A_26: #REF!
Name _10A_27: #REF!
Name _10A_28: #REF!
Name _10A_29: #REF!
Name _10A_3: #REF!
Name _10A_30: #REF!
Name _10A_31: #REF!
Name _10A_32: #REF!
Name _10A_33: #REF!
Name _10A_34: #REF!
Name _10A_35: #REF!
Name _10A_36: #REF!
Name _10A_37: #REF!
Name _10A_38: #REF!
Name _10A_39: #REF!
Name _10A_4: #REF!
Name _10A_40: #REF!
Name _10A_41: #REF!
Name _10A_42: #REF!
Name _10A_43: #REF!
Name _10A_44: #REF!
Name _10A_45: #REF!
Name _10A_46: #REF!
Name _10A_47: #REF!
Name _10A_48: #REF!
Name _10A_49: #REF!
Name _10A_5: #REF!
Name _10A_50: #REF!
Name _10A_51: #REF!
Name _10A_52: #REF!
Name _10A_53: #REF!

Sheet 화일명
B1: ■ 영상화일명 만들기
B3: NO | C3: 배관위치 | E3: 배관종류 | F3: 배관명 | G3: 이상소견 | H3: 이상위치 | I3: 예시
B4: 1 | C4: 동 | D4: 호 | E4: 입상관 | F4: 공용오수 | G4: 배관파손 | H4: <입상관> | I4: 배관위치+배관종류+배관명_이상소견_이상위치
F5: 공용배수 | G5: 부속파손 | H5: - 옥상바닥
F6: 부부오수 | G6: 연결불량 | H6: - 밴트연결부 | I6: ● 영상화일) 105동 3호 입상관 공용오수(이상배관)
F7: 부부배수 | G7: 패킹노출 | H7: - 호수(중간층-바닥기준으로 호수로 표시) | I7: => 앞으로 영상화일에는 '(이상배관)'으로 통일하여 표기
F8: 우수 | G8: 이물질 | H8: - 최하단 | I8: ▶ 사진명) 105동 3호 입상관 공용오수_이물질_밴트연결부
F9: 우수2 | G9: 이물질 떨어뜨림 | H9: - 횡주관연결부 | I9: ▶ 사진명) 105동 3호 입상관 공용오수_패킹노출_2003호
F10: 주방 | G10: 결빙
F11: 세탁 | G11: 막힘 | H11: <그외>
G12: 물고임 | H12: - 배관초입 | I12: ※ 앞으로 화일과 사진을 같이 보관
G13: 구배불량 | H13: - 배관중간
B14: 2 | C14: 동 | D14: 호 | E14: 횡주관 | F14: 오수 | G14: 배관누락 | H14: - 배관말 | I14: ● 영상화일) 105동 1-1호 횡주관 오수(이상배관)
F15: 배수 | G15: 배관연결오류 | H15: - 입상연결부 | I15: ▶ 사진명) 105동 1-1호 횡주관 오수_이물질_배관관말
F16: 우수 | G16: 주름관 노출 | H16: - 바닥
G17: 주름관 파손 | H17: - 천정
B18: 3 | C18: 동 | D18: 호 | E18: 세대매립관 | F18: 주방 | G18: 촬영불가 | I18: ● 영상화일) 105동 3호 세대매립관 주방(이상배관)
F19: 세탁 | G19: 진입불가 | I19: ▶ 사진명) 105동 3호 세대매립관 주방_파손_배관중간
F20: 발코니
B22: 4 | C22: 동 | D22: 호 | E22: 세대PD | F22: 공용욕실 | I22: ● 영상화일) 105동 3호 세대PD 공용욕실(이상배관)
F23: 부부욕실 | I23: ▶ 사진명) 105동 3호 세대PD 공용욕실_물고임_바닥
F24: 주방 | I24: ▶ 사진명) 105동 3호 세대PD 공용욕실_연결불량_천정
F25: 세탁
B27: 5 | C27: 동 | D27: 호 | E27: 세대층상배관 | F27: 공용욕실 | I27: ● 영상화일) 105동 3호 세대층상배관 부부(이상배관)
F28: 부부욕실 | I28: ▶ 사진명) 105동 3호 세대층상배관 부부_촬영불가_배간초입
B30: 6 | C30: 공통사항 | F30: 모든 영상화일 | I30: * 명판오류시)
I31: ● 영상화일) 105동 3호 층상배관 부부배수(명판오류)
I32: * 이상배관이 있을때)
I33: ● 영상화일) 105동 3호 층상배관 부부배수(이상배관)
I34: * 이상배관과 명판오류시)
I35: ● 영상화일) 105동 3호 층상배관 부부배수(이상배관)(명판오류)

Sheet 표지
C4: 배관내시경 점검 이상배관 보고
F12: 내시경 점검 회사명 : | L12: ㈜바로에코
F14: 점검자 : | I14: 이 준 철 | L14: (연락처: 010-2019-5782)
F16: ※ 당사 점검용 내시경 사양 기준
F17: - 화소수 : 90만 화소(해상도 1280*780)
F18: - 방수기능, LED등 포함
C28: 건축규모 : | F28: 지상 25층~30층, 10개동 / 공동주택( 1,000 세대) 및 부대복리시설
C29: 설 비 사 : | F29: 설비회사명 | N29: 시공책임자 : | R29: 홍 길 동
N30: 설비공구장 : | R30: 이 순 신

Sheet 입력창
B2: 입력창
B4: <현장명 : Sample아이파크>
B5: [설비사 : 바로설비]
G6: =SUM(H9:H51)
B7: 동명 | C7: 호수 | D7: 층수 | G7: 타입 | H7: 세대수 | I7: 입상관 | S7: 세대매립관 | X7: 세대PD | AC7: 세대층상배관
D8: 시작층 | E8: 특수층 | F8: 마지막층 | I8: 공용오수 | J8: 공용배수 | K8: 부부오수 | L8: 부부배수 | M8: 우수 | N8: 우수2 | O8: 주방 | P8: 세탁 | Q8: 기타1 | R8: 기타2 | S8: 주방 | T8: 세탁 | U8: 발코니 | V8: 기타1 | W8: 기타2 | X8: 공용욕실 | Y8: 부부욕실 | Z8: 주방 | AA8: 세탁 | AB8: 기타1 | AC8: 공용욕실 | AD8: 부부욕실 | AE8: 기타1
B9: 101 | C9: 1 | D9: 2 | F9: 25 | G9: 84A | H9: =+F9-D9+1 | I9: 1 | J9: 1 | K9: 1 | L9: 1 | M9: 1 | N9: 1 | O9: 1 | P9: 1 | S9: 1 | T9: 2 | X9: 1 | Y9: 2 | Z9: 3 | AA9: 4 | AC9: 1 | AD9: 2
B10: 101 | C10: 2 | D10: 2 | F10: 25 | G10: 84A | H10: =+F10-D10+1 | I10: 1 | J10: 1 | K10: 1 | L10: 1 | M10: 1 | N10: 1 | O10: 1 | P10: 1 | S10: 1 | T10: 2 | X10: 1 | Y10: 2 | Z10: 3 | AA10: 4 | AC10: 1 | AD10: 2
B11: 101 | C11: 3 | D11: 2 | F11: 25 | G11: 84A | H11: =+F11-D11+1 | I11: 1 | J11: 1 | K11: 1 | L11: 1 | M11: 1 | N11: 1 | O11: 1 | P11: 1 | S11: 1 | T11: 2 | X11: 1 | Y11: 2 | Z11: 3 | AA11: 4 | AC11: 1 | AD11: 2
B12: 101 | C12: 4 | D12: 2 | F12: 25 | G12: 84A | H12: =+F12-D12+1 | I12: 1 | J12: 1 | K12: 1 | L12: 1 | M12: 1 | N12: 1 | O12: 1 | P12: 1 | S12: 1 | T12: 2 | X12: 1 | Y12: 2 | Z12: 3 | AA12: 4 | AC12: 1 | AD12: 2
B13: 102 | C13: 1 | D13: 2 | F13: 30 | G13: 59B | H13: =+F13-D13+1 | I13: 1 | J13: 1 | K13: 1 | L13: 1 | M13: 1 | N13: 1 | O13: 1 | P13: 1 | S13: 1 | T13: 2 | X13: 1 | Y13: 2 | Z13: 3 | AA13: 4 | AC13: 1 | AD13: 2
B14: 102 | C14: 2 | D14: 2 | F14: 30 | G14: 84A | H14: =+F14-D14+1 | I14: 1 | J14: 1 | K14: 1 | L14: 1 | M14: 1 | N14: 1 | O14: 1 | P14: 1 | S14: 1 | T14: 2 | X14: 1 | Y14: 2 | Z14: 3 | AA14: 4 | AC14: 1 | AD14: 2
B15: 102 | C15: 3 | D15: 2 | F15: 30 | G15: 84A | H15: =+F15-D15+1 | I15: 1 | J15: 1 | K15: 1 | L15: 1 | M15: 1 | N15: 1 | O15: 1 | P15: 1 | S15: 1 | T15: 2 | X15: 1 | Y15: 2 | Z15: 3 | AA15: 4 | AC15: 1 | AD15: 2
B16: 102 | C16: 4 | D16: 2 | F16: 30 | G16: 84A | H16: =+F16-D16+1 | I16: 1 | J16: 1 | K16: 1 | L16: 1 | M16: 1 | N16: 1 | O16: 1 | P16: 1 | S16: 1 | T16: 2 | X16: 1 | Y16: 2 | Z16: 3 | AA16: 4 | AC16: 1 | AD16: 2
B17: 103 | C17: 1 | D17: 1 | F17: 25 | G17: 104 | H17: =+F17-D17+1 | I17: 1 | J17: 1 | K17: 1 | L17: 1 | M17: 1 | N17: 1 | O17: 1 | P17: 1 | S17: 1 | T17: 2 | U17: 3 | X17: 1 | Y17: 2 | Z17: 3 | AA17: 4 | AC17: 1 | AD17: 2
B18: 103 | C18: 2 | D18: 1 | F18: 25 | G18: 104 | H18: =+F18-D18+1 | I18: 1 | J18: 1 | K18: 1 | L18: 1 | M18: 1 | N18: 1 | O18: 1 | P18: 1 | S18: 1 | T18: 2 | U18: 3 | X18: 1 | Y18: 2 | Z18: 3 | AA18: 4 | AC18: 1 | AD18: 2
B19: 103 | C19: 3 | D19: 1 | F19: 25 | G19: 84B | H19: =+F19-D19+1 | I19: 1 | J19: 1 | K19: 1 | L19: 1 | M19: 1 | N19: 1 | O19: 1 | P19: 1 | S19: 1 | T19: 2 | X19: 1 | Y19: 2 | Z19: 3 | AA19: 4 | AC19: 1 | AD19: 2
B20: 103 | C20: 4 | D20: 1 | F20: 25 | G20: 84B | H20: =+F20-D20+1 | I20: 1 | J20: 1 | K20: 1 | L20: 1 | M20: 1 | N20: 1 | O20: 1 | P20: 1 | S20: 1 | T20: 2 | X20: 1 | Y20: 2 | Z20: 3 | AA20: 4 | AC20: 1 | AD20: 2
B21: 103 | C21: 5 | D21: 1 | F21: 25 | G21: 84B | H21: =+F21-D21+1 | I21: 1 | J21: 1 | K21: 1 | L21: 1 | M21: 1 | N21: 1 | O21: 1 | P21: 1 | S21: 1 | T21: 2 | X21: 1 | Y21: 2 | Z21: 3 | AA21: 4 | AC21: 1 | AD21: 2
B22: 104 | C22: 1 | D22: 2 | F22: 27 | G22: 84C | H22: =+F22-D22+1 | I22: 1 | J22: 1 | K22: 1 | L22: 1 | M22: 1 | N22: 1 | O22: 1 | P22: 1 | S22: 1 | T22: 2 | X22: 1 | Y22: 2 | Z22: 3 | AA22: 4 | AC22: 1 | AD22: 2
B23: 104 | C23: 2 | D23: 2 | F23: 27 | G23: 84C | H23: =+F23-D23+1 | I23: 1 | J23: 1 | K23: 1 | L23: 1 | M23: 1 | N23: 1 | O23: 1 | P23: 1 | S23: 1 | T23: 2 | X23: 1 | Y23: 2 | Z23: 3 | AA23: 4 | AC23: 1 | AD23: 2
B24: 104 | C24: 3 | D24: 2 | F24: 26 | G24: 84C | H24: =+F24-D24+1 | I24: 1 | J24: 1 | K24: 1 | L24: 1 | M24: 1 | N24: 1 | O24: 1 | P24: 1 | S24: 1 | T24: 2 | X24: 1 | Y24: 2 | Z24: 3 | AA24: 4 | AC24: 1 | AD24: 2
B25: 104 | C25: 4 | D25: 2 | F25: 25 | G25: 84C | H25: =+F25-D25+1 | I25: 1 | J25: 1 | K25: 1 | L25: 1 | M25: 1 | N25: 1 | O25: 1 | P25: 1 | S25: 1 | T25: 2 | X25: 1 | Y25: 2 | Z25: 3 | AA25: 4 | AC25: 1 | AD25: 2
B26: 104 | C26: 5 | D26: 2 | F26: 25 | G26: 84C | H26: =+F26-D26+1 | I26: 1 | J26: 1 | K26: 1 | L26: 1 | M26: 1 | N26: 1 | O26: 1 | P26: 1 | S26: 1 | T26: 2 | X26: 1 | Y26: 2 | Z26: 3 | AA26: 4 | AC26: 1 | AD26: 2
B27: 104 | C27: 6 | D27: 2 | F27: 25 | G27: 84C | H27: =+F27-D27+1 | I27: 1 | J27: 1 | K27: 1 | L27: 1 | M27: 1 | N27: 1 | O27: 1 | P27: 1 | S27: 1 | T27: 2 | X27: 1 | Y27: 2 | Z27: 3 | AA27: 4 | AC27: 1 | AD27: 2
B28: 105 | C28: 1 | D28: 2 | F28: 25 | G28: 49A | H28: =+F28-D28+1 | I28: 1 | J28: 1 | M28: 1 | O28: 1 | P28: 1 | S28: 1 | T28: 2 | X28: 1 | Y28: 2 | Z28: 3 | AC28: 1
B29: 105 | C29: 2 | D29: 2 | F29: 25 | G29: 49A | H29: =+F29-D29+1 | I29: 1 | J29: 1 | M29: 1 | O29: 1 | P29: 1 | S29: 1 | T29: 2 | X29: 1 | Y29: 2 | Z29: 3 | AC29: 1
B30: 105 | C30: 3 | D30: 2 | F30: 25 | G30: 49A | H30: =+F30-D30+1 | I30: 1 | J30: 1 | M30: 1 | O30: 1 | P30: 1 | S30: 1 | T30: 2 | X30: 1 | Y30: 2 | Z30: 3 | AC30: 1
B31: 105 | C31: 4 | D31: 2 | F31: 25 | G31: 49A | H31: =+F31-D31+1 | I31: 1 | J31: 1 | M31: 1 | O31: 1 | P31: 1 | S31: 1 | T31: 2 | X31: 1 | Y31: 2 | Z31: 3 | AC31: 1
B32: 106 | C32: 1 | D32: 1 | F32: 15 | G32: 84A | H32: =+F32-D32+1 | I32: 1 | J32: 1 | K32: 1 | L32: 1 | M32: 1 | N32: 1 | O32: 1 | P32: 1 | S32: 1 | T32: 2 | X32: 1 | Y32: 2 | Z32: 3 | AA32: 4 | AC32: 1 | AD32: 2
B33: 106 | C33: 2 | D33: 1 | F33: 15 | G33: 84A | H33: =+F33-D33+1 | I33: 1 | J33: 1 | K33: 1 | L33: 1 | M33: 1 | N33: 1 | O33: 1 | P33: 1 | S33: 1 | T33: 2 | X33: 1 | Y33: 2 | Z33: 3 | AA33: 4 | AC33: 1 | AD33: 2
B34: 106 | C34: 3 | D34: 1 | F34: 15 | G34: 84A | H34: =+F34-D34+1 | I34: 1 | J34: 1 | K34: 1 | L34: 1 | M34: 1 | N34: 1 | O34: 1 | P34: 1 | S34: 1 | T34: 2 | X34: 1 | Y34: 2 | Z34: 3 | AA34: 4 | AC34: 1 | AD34: 2
B35: 106 | C35: 4 | D35: 1 | F35: 15 | G35: 84A | H35: =+F35-D35+1 | I35: 1 | J35: 1 | K35: 1 | L35: 1 | M35: 1 | N35: 1 | O35: 1 | P35: 1 | S35: 1 | T35: 2 | X35: 1 | Y35: 2 | Z35: 3 | AA35: 4 | AC35: 1 | AD35: 2
B36: 107 | C36: 1 | D36: 2 | F36: 25 | G36: 84A | H36: =+F36-D36+1 | I36: 1 | J36: 1 | K36: 1 | L36: 1 | M36: 1 | N36: 1 | O36: 1 | P36: 1 | S36: 1 | T36: 2 | X36: 1 | Y36: 2 | Z36: 3 | AA36: 4 | AC36: 1 | AD36: 2
B37: 107 | C37: 2 | D37: 2 | F37: 25 | G37: 84A | H37: =+F37-D37+1 | I37: 1 | J37: 1 | K37: 1 | L37: 1 | M37: 1 | N37: 1 | O37: 1 | P37: 1 | S37: 1 | T37: 2 | X37: 1 | Y37: 2 | Z37: 3 | AA37: 4 | AC37: 1 | AD37: 2
B38: 107 | C38: 3 | D38: 2 | F38: 25 | G38: 84A | H38: =+F38-D38+1 | I38: 1 | J38: 1 | K38: 1 | L38: 1 | M38: 1 | N38: 1 | O38: 1 | P38: 1 | S38: 1 | T38: 2 | X38: 1 | Y38: 2 | Z38: 3 | AA38: 4 | AC38: 1 | AD38: 2
B39: 107 | C39: 4 | D39: 2 | F39: 25 | G39: 84A | H39: =+F39-D39+1 | I39: 1 | J39: 1 | K39: 1 | L39: 1 | M39: 1 | N39: 1 | O39: 1 | P39: 1 | S39: 1 | T39: 2 | X39: 1 | Y39: 2 | Z39: 3 | AA39: 4 | AC39: 1 | AD39: 2
B40: 108 | C40: 1 | D40: 2 | F40: 25 | G40: 84A | H40: =+F40-D40+1 | I40: 1 | J40: 1 | K40: 1 | L40: 1 | M40: 1 | N40: 1 | O40: 1 | P40: 1 | S40: 1 | T40: 2 | X40: 1 | Y40: 2 | Z40: 3 | AA40: 4 | AC40: 1 | AD40: 2
B41: 108 | C41: 2 | D41: 2 | F41: 25 | G41: 84A | H41: =+F41-D41+1 | I41: 1 | J41: 1 | K41: 1 | L41: 1 | M41: 1 | N41: 1 | O41: 1 | P41: 1 | S41: 1 | T41: 2 | X41: 1 | Y41: 2 | Z41: 3 | AA41: 4 | AC41: 1 | AD41: 2
B42: 108 | C42: 3 | D42: 2 | F42: 20 | G42: 84A | H42: =+F42-D42+1 | I42: 1 | J42: 1 | K42: 1 | L42: 1 | M42: 1 | N42: 1 | O42: 1 | P42: 1 | S42: 1 | T42: 2 | X42: 1 | Y42: 2 | Z42: 3 | AA42: 4 | AC42: 1 | AD42: 2
...

Sheet 1.작업현황_입상관
B1: ■ 입상관 작업현황 | O1: 입상관
B2: =+입력창!B4 | Q2: =+입력창!B5
B3: 동 | C3: 라인 | D3: 층수 | E3: 타입 | F3: 세대수 | G3: 공용오수 | H3: 공용배수 | I3: 부부오수 | J3: 부부배수 | K3: 우수 | L3: 우수2 | M3: 주방배수 | N3: 세탁배수 | O3: 기타1 | P3: 기타2 | Q3: 점검 일시
B4: 101 | C4: 1 | D4: 25 | E4: 84A | F4: 24 | K4: 완료 | L4: 이상배관
C5: 2 | D5: 25 | E5: 84A | F5: 24
C6: 3 | D6: 25 | E6: 84A | F6: 24 | K6: 이상배관 | L6: 이상배관
C7: 4 | D7: 25 | E7: 84A | F7: 24
B8: 102 | C8: 1 | D8: 30 | E8: 59B | F8: 29
C9: 2 | D9: 30 | E9: 84A | F9: 29 | L9: 패킹불량
C10: 3 | D10: 30 | E10: 84A | F10: 29
C11: 4 | D11: 30 | E11: 84A | F11: 29
B12: 103 | C12: 1 | D12: 25 | E12: 104 | F12: 25
C13: 2 | D13: 25 | E13: 104 | F13: 25
C14: 3 | D14: 25 | E14: 84B | F14: 25
C15: 4 | D15: 25 | E15: 84B | F15: 25
C16: 5 | D16: 25 | E16: 84B | F16: 25
B17: 104 | C17: 1 | D17: 27 | E17: 84C | F17: 26
C18: 2 | D18: 27 | E18: 84C | F18: 26
C19: 3 | D19: 26 | E19: 84C | F19: 25
C20: 4 | D20: 25 | E20: 84C | F20: 24
C21: 5 | D21: 25 | E21: 84C | F21: 24
C22: 6 | D22: 25 | E22: 84C | F22: 24
B23: 105 | C23: 1 | D23: 25 | E23: 49A | F23: 24
C24: 2 | D24: 25 | E24: 49A | F24: 24
C25: 3 | D25: 25 | E25: 49A | F25: 24
C26: 4 | D26: 25 | E26: 49A | F26: 24
B27: 106 | C27: 1 | D27: 15 | E27: 84A | F27: 15
C28: 2 | D28: 15 | E28: 84A | F28: 15
C29: 3 | D29: 15 | E29: 84A | F29: 15
C30: 4 | D30: 15 | E30: 84A | F30: 15
B31: 107 | C31: 1 | D31: 25 | E31: 84A | F31: 24
C32: 2 | D32: 25 | E32: 84A | F32: 24
C33: 3 | D33: 25 | E33: 84A | F33: 24
C34: 4 | D34: 25 | E34: 84A | F34: 24
B35: 108 | C35: 1 | D35: 25 | E35: 84A | F35: 24
C36: 2 | D36: 25 | E36: 84A | F36: 24
C37: 3 | D37: 20 | E37: 84A | F37: 19
C38: 4 | D38: 20 | E38: 84A | F38: 19
B39: 109 | C39: 1 | D39: 25 | E39: 84A | F39: 24
C40: 2 | D40: 25 | E40: 84A | F40: 24
...

Sheet 2.이상배관위치_입상관
A1: ■ 입상관 작업현황 | AG1: 입상관 | BP1: 입상관
A2: =+입력창!B4
B8: 101동 | I8: 102동 | P8: 103동 | X8: 104동 | AG8: 105동 | AN8: 106동 | AU8: 107동 | BB8: 108동 | BI8: 109동 | BP8: 110동
H11: 30층 | I11: 3001 | J11: 3002 | K11: 3003 | L11: 3004 | M11: 1'
H12: 29층 | I12: 2901 | J12: 2902 | K12: 2903 | L12: 2904 | M12: 2'
H13: 28층 | I13: 2801 | J13: 2802 | K13: 2803 | L13: 2804 | M13: 3'
H14: 27층 | I14: 2701 | J14: 2702 | K14: 2703 | L14: 2704 | M14: 4' | W14: 27층 | X14: 2701 | Y14: 2702 | AD14: 1'
H15: 26층 | I15: 2601 | J15: 2602 | K15: 2603 | L15: 2604 | M15: 5' | W15: 26층 | X15: 2601 | Y15: 2602 | Z15: 2603 | AD15: 2'
A16: 25층 | B16: 2501 | C16: 2502 | D16: 2503 | E16: 2504 | F16: 1' | H16: 25층 | I16: 2501 | J16: 2502 | K16: 2503 | L16: 2504 | M16: 6' | O16: 25층 | P16: 2501 | Q16: 2502 | R16: 2503 | S16: 2504 | T16: 2505 | U16: 1' | W16: 25층 | X16: 2501 | Y16: 2502 | Z16: 2503 | AA16: 2504 | AB16: 2504 | AC16: 2505 | AD16: 3' | AF16: 25층 | AG16: 2501 | AH16: 2502 | AI16: 2503 | AJ16: 2504 | AK16: 1' | AT16: 25층 | AU16: 2501 | AV16: 2502 | AW16: 2503 | AX16: 2504 | AY16: 1' | BA16: 25층 | BB16: 2501 | BC16: 2502 | BF16: 1' | BH16: 25층 | BI16: 2501 | BJ16: 2502 | BK16: 2503 | BL16: 2504 | BM16: 1'
A17: 24층 | B17: 2401 | C17: 2402 | D17: 2403 | E17: 2404 | F17: 2' | H17: 24층 | I17: 2401 | J17: 2402 | K17: 2403 | L17: 2404 | M17: 7' | O17: 24층 | P17: 2401 | Q17: 2402 | R17: 2403 | S17: 2404 | T17: 2405 | U17: 2' | W17: 24층 | X17: 2401 | Y17: 2402 | Z17: 2403 | AA17: 2404 | AB17: 2404 | AC17: 2405 | AD17: 4' | AF17: 24층 | AG17: 2401 | AH17: 2402 | AI17: 2403 | AJ17: 2404 | AK17: 2' | AT17: 24층 | AU17: 2401 | AV17: 2402 | AW17: 2403 | AX17: 2404 | AY17: 2' | BA17: 24층 | BB17: 2401 | BC17: 2402 | BF17: 2' | BH17: 24층 | BI17: 2401 | BJ17: 2402 | BK17: 2403 | BL17: 2404 | BM17: 2'
A18: 23층 | B18: 2301 | C18: 2302 | D18: 2303 | E18: 2304 | F18: 3' | H18: 23층 | I18: 2301 | J18: 2302 | K18: 2303 | L18: 2304 | M18: 8' | O18: 23층 | P18: 2301 | Q18: 2302 | R18: 2303 | S18: 2304 | T18: 2305 | U18: 3' | W18: 23층 | X18: 2301 | Y18: 2302 | Z18: 2303 | AA18: 2304 | AB18: 2304 | AC18: 2305 | AD18: 5' | AF18: 23층 | AG18: 2301 | AH18: 2302 | AI18: 2303 | AJ18: 2304 | AK18: 3' | AT18: 23층 | AU18: 2301 | AV18: 2302 | AW18: 2303 | AX18: 2304 | AY18: 3' | BA18: 23층 | BB18: 2301 | BC18: 2302 | BF18: 3' | BH18: 23층 | BI18: 2301 | BJ18: 2302 | BK18: 2303 | BL18: 2304 | BM18: 3'
A19: 22층 | B19: 2201 | C19: 2202 | D19: 2203 | E19: 2204 | F19: 4' | H19: 22층 | I19: 2201 | J19: 2202 | K19: 2203 | L19: 2204 | M19: 9' | O19: 22층 | P19: 2201 | Q19: 2202 | R19: 2203 | S19: 2204 | T19: 2205 | U19: 4' | W19: 22층 | X19: 2201 | Y19: 2202 | Z19: 2203 | AA19: 2204 | AB19: 2204 | AC19: 2205 | AD19: 6' | AF19: 22층 | AG19: 2201 | AH19: 2202 | AI19: 2203 | AJ19: 2204 | AK19: 4' | AT19: 22층 | AU19: 2201 | AV19: 2202 | AW19: 2203 | AX19: 2204 | AY19: 4' | BA19: 22층 | BB19: 2201 | BC19: 2202 | BF19: 4' | BH19: 22층 | BI19: 2201 | BJ19: 2202 | BK19: 2203 | BL19: 2204 | BM19: 4'
A20: 21층 | B20: 2101 | C20: 2102 | D20: 2103 | E20: 2104 | F20: 5' | H20: 21층 | I20: 2101 | J20: 2102 | K20: 2103 | L20: 2104 | M20: 10' | O20: 21층 | P20: 2101 | Q20: 2102 | R20: 2103 | S20: 2104 | T20: 2105 | U20: 5' | W20: 21층 | X20: 2101 | Y20: 2102 | Z20: 2103 | AA20: 2104 | AB20: 2104 | AC20: 2105 | AD20: 7' | AF20: 21층 | AG20: 2101 | AH20: 2102 | AI20: 2103 | AJ20: 2104 | AK20: 5' | AT20: 21층 | AU20: 2101 | AV20: 2102 | AW20: 2103 | AX20: 2104 | AY20: 5' | BA20: 21층 | BB20: 2101 | BC20: 2102 | BF20: 5' | BH20: 21층 | BI20: 2101 | BJ20: 2102 | BK20: 2103 | BL20: 2104 | BM20: 5'
A21: 20층 | B21: 2001 | C21: 2002 | D21: 2003 | E21: 2004 | F21: 6' | H21: 20층 | I21: 2001 | J21: 2002 | K21: 2003 | L21: 2004 | M21: 11' | O21: 20층 | P21: 2001 | Q21: 2002 | R21: 2003 | S21: 2004 | T21: 2005 | U21: 6' | W21: 20층 | X21: 2001 | Y21: 2002 | Z21: 2003 | AA21: 2004 | AB21: 2004 | AC21: 2005 | AD21: 8' | AF21: 20층 | AG21: 2001 | AH21: 2002 | AI21: 2003 | AJ21: 2004 | AK21: 6' | AT21: 20층 | AU21: 2001 | AV21: 2002 | AW21: 2003 | AX21: 2004 | AY21: 6' | BA21: 20층 | BB21: 2001 | BC21: 2002 | BD21: 2003 | BE21: 2004 | BF21: 6' | BH21: 20층 | BI21: 2001 | BJ21: 2002 | BK21: 2003 | BL21: 2004 | BM21: 6' | BO21: 20층 | BP21: 2001 | BQ21: 2002 | BR21: 2003 | BS21: 2004 | BT21: 1'
A22: 19층 | B22: 1901 | C22: 1902 | D22: 1903 | E22: 1904 | F22: 7' | H22: 19층 | I22: 1901 | J22: 1902 | K22: 1903 | L22: 1904 | M22: 12' | O22: 19층 | P22: 1901 | Q22: 1902 | R22: 1903 | S22: 1904 | T22: 1905 | U22: 7' | W22: 19층 | X22: 1901 | Y22: 1902 | Z22: 1903 | AA22: 1904 | AB22: 1904 | AC22: 1905 | AD22: 9' | AF22: 19층 | AG22: 1901 | AH22: 1902 | AI22: 1903 | AJ22: 1904 | AK22: 7' | AT22: 19층 | AU22: 1901 | AV22: 1902 | AW22: 1903 | AX22: 1904 | AY22: 7' | BA22: 19층 | BB22: 1901 | BC22: 1902 | BD22: 1903 | BE22: 1904 | BF22: 7' | BH22: 19층 | BI22: 1901 | BJ22: 1902 | BK22: 1903 | BL22: 1904 | BM22: 7' | BO22: 19층 | BP22: 1901 | BQ22: 1902 | BR22: 1903 | BS22: 1904 | BT22: 2'
A23: 18층 | B23: 1801 | C23: 1802 | D23: 1803 | E23: 1804 | F23: 8' | H23: 18층 | I23: 1801 | J23: 1802 | K23: 1803 | L23: 1804 | M23: 13' | O23: 18층 | P23: 1801 | Q23: 1802 | R23: 1803 | S23: 1804 | T23: 1805 | U23: 8' | W23: 18층 | X23: 1801 | Y23: 1802 | Z23: 1803 | AA23: 1804 | AB23: 1804 | AC23: 1805 | AD23: 10' | AF23: 18층 | AG23: 1801 | AH23: 1802 | AI23: 1803 | AJ23: 1804 | AK23: 8' | AT23: 18층 | AU23: 1801 | AV23: 1802 | AW23: 1803 | AX23: 1804 | AY23: 8' | BA23: 18층 | BB23: 1801 | BC23: 1802 | BD23: 1803 | BE23: 1804 | BF23: 8' | BH23: 18층 | BI23: 1801 | BJ23: 1802 | BK23: 1803 | BL23: 1804 | BM23: 8' | BO23: 18층 | BP23: 1801 | BQ23: 1802 | BR23: 1803 | BS23: 1804 | BT23: 3'
A24: 17층 | B24: 1701 | C24: 1702 | D24: 1703 | E24: 1704 | F24: 9' | H24: 17층 | I24: 1701 | J24: 1702 | K24: 1703 | L24: 1704 | M24: 14' | O24: 17층 | P24: 1701 | Q24: 1702 | R24: 1703 | S24: 1704 | T24: 1705 | U24: 9' | W24: 17층 | X24: 1701 | Y24: 1702 | Z24: 1703 | AA24: 1704 | AB24: 1704 | AC24: 1705 | AD24: 11' | AF24: 17층 | AG24: 1701 | AH24: 1702 | AI24: 1703 | AJ24: 1704 | AK24: 9' | AT24: 17층 | AU24: 1701 | AV24: 1702 | AW24: 1703 | AX24: 1704 | AY24: 9' | BA24: 17층 | BB24: 1701 | BC24: 1702 | BD24: 1703 | BE24: 1704 | BF24: 9' | BH24: 17층 | BI24: 1701 | BJ24: 1702 | BK24: 1703 | BL24: 1704 | BM24: 9' | BO24: 17층 | BP24: 1701 | BQ24: 1702 | BR24: 1703 | BS24: 1704 | BT24: 4'
A25: 16층 | B25: 1601 | C25: 1602 | D25: 1603 | E25: 1604 | F25: 10' | H25: 16층 | I25: 1601 | J25: 1602 | K25: 1603 | L25: 1604 | M25: 15' | O25: 16층 | P25: 1601 | Q25: 1602 | R25: 1603 | S25: 1604 | T25: 1605 | U25: 10' | W25: 16층 | X25: 1601 | Y25: 1602 | Z25: 1603 | AA25: 1604 | AB25: 1604 | AC25: 1605 | AD25: 12' | AF25: 16층 | AG25: 1601 | AH25: 1602 | AI25: 1603 | AJ25: 1604 | AK25: 10' | AT25: 16층 | AU25: 1601 | AV25: 1602 | AW25: 1603 | AX25: 1604 | AY25: 10' | BA25: 16층 | BB25: 1601 | BC25: 1602 | BD25: 1603 | BE25: 1604 | BF25: 10' | BH25: 16층 | BI25: 1601 | BJ25: 1602 | BK25: 1603 | BL25: 1604 | BM25: 10' | BO25: 16층 | BP25: 1601 | BQ25: 1602 | BR25: 1603 | BS25: 1604 | BT25: 5'
A26: 15층 | B26: 1501 | C26: 1502 | D26: 1503 | E26: 1504 | F26: 11' | H26: 15층 | I26: 1501 | J26: 1502 | K26: 1503 | L26: 1504 | M26: 16' | O26: 15층 | P26: 1501 | Q26: 1502 | R26: 1503 | S26: 1504 | T26: 1505 | U26: 11' | W26: 15층 | X26: 1501 | Y26: 1502 | Z26: 1503 | AA26: 1504 | AB26: 1504 | AC26: 1505 | AD26: 13' | AF26: 15층 | AG26: 1501 | AH26: 1502 | AI26: 1503 | AJ26: 1504 | AK26: 11' | AM26: 15층 | AN26: 1501 | AO26: 1502 | AP26: 1503 | AQ26: 1504 | AR26: 1' | AT26: 15층 | AU26: 1501 | AV26: 1502 | AW26: 1503 | AX26: 1504 | AY26: 11' | BA26: 15층 | BB26: 1501 | BC26: 1502 | BD26: 1503 | BE26: 1504 | BF26: 11' | BH26: 15층 | BI26: 1501 | BJ26: 1502 | BK26: 1503 | BL26: 1504 | BM26: 11' | BO26: 15층 | BP26: 1501 | BQ26: 1502 | BR26: 1503 | BS26: 1504 | BT26: 6'
A27: 14층 | B27: 1401 | C27: 1402 | D27: 1403 | E27: 1404 | F27: 12' | H27: 14층 | I27: 1401 | J27: 1402 | K27: 1403 | L27: 1404 | M27: 17' | O27: 14층 | P27: 1401 | Q27: 1402 | R27: 1403 | S27: 1404 | T27: 1405 | U27: 12' | W27: 14층 | X27: 1401 | Y27: 1402 | Z27: 1403 | AA27: 1404 | AB27: 1404 | AC27: 1405 | AD27: 14' | AF27: 14층 | AG27: 1401 | AH27: 1402 | AI27: 1403 | AJ27: 1404 | AK27: 12' | AM27: 14층 | AN27: 1401 | AO27: 1402 | AP27: 1403 | AQ27: 1404 | AR27: 2' | AT27: 14층 | AU27: 1401 | AV27: 1402 | AW27: 1403 | AX27: 1404 | AY27: 12' | BA27: 14층 | BB27: 1401 | BC27: 1402 | BD27: 1403 | BE27: 1404 | BF27: 12' | BH27: 14층 | BI27: 1401 | BJ27: 1402 | BK27: 1403 | BL27: 1404 | BM27: 12' | BO27: 14층 | BP27: 1401 | BQ27: 1402 | BR27: 1403 | BS27: 1404 | BT27: 7'
A28: 13층 | B28: 1301 | C28: 1302 | D28: 1303 | E28: 1304 | F28: 13' | H28: 13층 | I28: 1301 | J28: 1302 | K28: 1303 | L28: 1304 | M28: 18' | O28: 13층 | P28: 1301 | Q28: 1302 | R28: 1303 | S28: 1304 | T28: 1305 | U28: 13' | W28: 13층 | X28: 1301 | Y28: 1302 | Z28: 1303 | AA28: 1304 | AB28: 1304 | AC28: 1305 | AD28: 15' | AF28: 13층 | AG28: 1301 | AH28: 1302 | AI28: 1303 | AJ28: 1304 | AK28: 13' | AM28: 13층 | AN28: 1301 | AO28: 1302 | AP28: 1303 | AQ28: 1304 | AR28: 3' | AT28: 13층 | AU28: 1301 | AV28: 1302 | AW28: 1303 | AX28: 1304 | AY28: 13' | BA28: 13층 | BB28: 1301 | BC28: 1302 | BD28: 1303 | BE28: 1304 | BF28: 13' | BH28: 13층 | BI28: 1301 | BJ28: 1302 | BK28: 1303 | BL28: 1304 | BM28: 13' | BO28: 13층 | BP28: 1301 | BQ28: 1302 | BR28: 1303 | BS28: 1304 | BT28: 8'
A29: 12층 | B29: 1201 | C29: 1202 | D29: 1203 | E29: 1204 | F29: 14' | H29: 12층 | I29: 1201 | J29: 1202 | K29: 1203 | L29: 1204 | M29: 19' | O29: 12층 | P29: 1201 | Q29: 1202 | R29: 1203 | S29: 1204 | T29: 1205 | U29: 14' | W29: 12층 | X29: 1201 | Y29: 1202 | Z29: 1203 | AA29: 1204 | AB29: 1204 | AC29: 1205 | AD29: 16' | AF29: 12층 | AG29: 1201 | AH29: 1202 | AI29: 1203 | AJ29: 1204 | AK29: 14' | AM29: 12층 | AN29: 1201 | AO29: 1202 | AP29: 1203 | AQ29: 1204 | AR29: 4' | AT29: 12층 | AU29: 1201 | AV29: 1202 | AW29: 1203 | AX29: 1204 | AY29: 14' | BA29: 12층 | BB29: 1201 | BC29: 1202 | BD29: 1203 | BE29: 1204 | BF29: 14' | BH29: 12층 | BI29: 1201 | BJ29: 1202 | BK29: 1203 | BL29: 1204 | BM29: 14' | BO29: 12층 | BP29: 1201 | BQ29: 1202 | BR29: 1203 | BS29: 1204 | BT29: 9'
A30: 11층 | B30: 1101 | C30: 1102 | D30: 1103 | E30: 1104 | F30: 15' | H30: 11층 | I30: 1101 | J30: 1102 | K30: 1103 | L30: 1104 | M30: 20' | O30: 11층 | P30: 1101 | Q30: 1102 | R30: 1103 | S30: 1104 | T30: 1105 | U30: 15' | W30: 11층 | X30: 1101 | Y30: 1102 | Z30: 1103 | AA30: 1104 | AB30: 1104 | AC30: 1105 | AD30: 17' | AF30: 11층 | AG30: 1101 | AH30: 1102 | AI30: 1103 | AJ30: 1104 | AK30: 15' | AM30: 11층 | AN30: 1101 | AO30: 1102 | AP30: 1103 | AQ30: 1104 | AR30: 5' | AT30: 11층 | AU30: 1101 | AV30: 1102 | AW30: 1103 | AX30: 1104 | AY30: 15' | BA30: 11층 | BB30: 1101 | BC30: 1102 | BD30: 1103 | BE30: 1104 | BF30: 15' | BH30: 11층 | BI30: 1101 | BJ30: 1102 | BK30: 1103 | BL30: 1104 | BM30: 15' | BO30: 11층 | BP30: 1101 | BQ30: 1102 | BR30: 1103 | BS30: 1104 | BT30: 10'
A31: 10층 | B31: 1001 | C31: 1002 | D31: 1003 | E31: 1004 | F31: 16' | H31: 10층 | I31: 1001 | J31: 1002 | K31: 1003 | L31: 1004 | M31: 21' | O31: 10층 | P31: 1001 | Q31: 1002 | R31: 1003 | S31: 1004 | T31: 1005 | U31: 16' | W31: 10층 | X31: 1001 | Y31: 1002 | Z31: 1003 | AA31: 1004 | AB31: 1004 | AC31: 1005 | AD31: 18' | AF31: 10층 | AG31: 1001 | AH31: 1002 | AI31: 1003 | AJ31: 1004 | AK31: 16' | AM31: 10층 | AN31: 1001 | AO31: 1002 | AP31: 1003 | AQ31: 1004 | AR31: 6' | AT31: 10층 | AU31: 1001 | AV31: 1002 | AW31: 1003 | AX31: 1004 | AY31: 16' | BA31: 10층 | BB31: 1001 | BC31: 1002 | BD31: 1003 | BE31: 1004 | BF31: 16' | BH31: 10층 | BI31: 1001 | BJ31: 1002 | BK31: 1003 | BL31: 1004 | BM31: 16' | BO31: 10층 | BP31: 1001 | BQ31: 1002 | BR31: 1003 | BS31: 1004 | BT31: 11'
A32: 9층 | B32: 901 | C32: 902 | D32: 903 | E32: 904 | F32: 17' | H32: 9층 | I32: 901 | J32: 902 | K32: 903 | L32: 904 | M32: 22' | O32: 9층 | P32: 901 | Q32: 902 | R32: 903 | S32: 904 | T32: 905 | U32: 17' | W32: 9층 | X32: 901 | Y32: 902 | Z32: 903 | AA32: 904 | AB32: 904 | AC32: 905 | AD32: 19' | AF32: 9층 | AG32: 901 | AH32: 902 | AI32: 903 | AJ32: 904 | AK32: 17' | AM32: 9층 | AN32: 901 | AO32: 902 | AP32: 903 | AQ32: 904 | AR32: 7' | AT32: 9층 | AU32: 901 | AV32: 902 | AW32: 903 | AX32: 904 | AY32: 17' | BA32: 9층 | BB32: 901 | BC32: 902 | BD32: 903 | BE32: 904 | BF32: 17' | BH32: 9층 | BI32: 901 | BJ32: 902 | BK32: 903 | BL32: 904 | BM32: 17' | BO32: 9층 | BP32: 901 | BQ32: 902 | BR32: 903 | BS32: 904 | BT32: 12'
A33: 8층 | B33: 801 | C33: 802 | D33: 803 | E33: 804 | F33: 18' | H33: 8층 | I33: 801 | J33: 802 | K33: 803 | L33: 804 | M33: 23' | O33: 8층 | P33: 801 | Q33: 802 | R33: 803 | S33: 804 | T33: 805 | U33: 18' | W33: 8층 | X33: 801 | Y33: 802 | Z33: 803 | AA33: 804 | AB33: 804 | AC33: 805 | AD33: 20' | AF33: 8층 | AG33: 801 | AH33: 802 | AI33: 803 | AJ33: 804 | AK33: 18' | AM33: 8층 | AN33: 801 | AO33: 802 | AP33: 803 | AQ33: 804 | AR33: 8' | AT33: 8층 | AU33: 801 | AV33: 802 | AW33: 803 | AX33: 804 | AY33: 18' | BA33: 8층 | BB33: 801 | BC33: 802 | BD33: 803 | BE33: 804 | BF33: 18' | BH33: 8층 | BI33: 801 | BJ33: 802 | BK33: 803 | BL33: 804 | BM33: 18' | BO33: 8층 | BP33: 801 | BQ33: 802 | BR33: 803 | BS33: 804 | BT33: 13'
A34: 7층 | B34: 701 | C34: 702 | D34: 703 | E34: 704 | F34: 19' | H34: 7층 | I34: 701 | J34: 702 | K34: 703 | L34: 704 | M34: 24' | O34: 7층 | P34: 701 | Q34: 702 | R34: 703 | S34: 704 | T34: 705 | U34: 19' | W34: 7층 | X34: 701 | Y34: 702 | Z34: 703 | AA34: 704 | AB34: 704 | AC34: 705 | AD34: 21' | AF34: 7층 | AG34: 701 | AH34: 702 | AI34: 703 | AJ34: 704 | AK34: 19' | AM34: 7층 | AN34: 701 | AO34: 702 | AP34: 703 | AQ34: 704 | AR34: 9' | AT34: 7층 | AU34: 701 | AV34: 702 | AW34: 703 | AX34: 704 | AY34: 19' | BA34: 7층 | BB34: 701 | BC34: 702 | BD34: 703 | BE34: 704 | BF34: 19' | BH34: 7층 | BI34: 701 | BJ34: 702 | BK34: 703 | BL34: 704 | BM34: 19' | BO34: 7층 | BP34: 701 | BQ34: 702 | BR34: 703 | BS34: 704 | BT34: 14'
A35: 6층 | B35: 601 | C35: 602 | D35: 603 | E35: 604 | F35: 20' | H35: 6층 | I35: 601 | J35: 602 | K35: 603 | L35: 604 | M35: 25' | O35: 6층 | P35: 601 | Q35: 602 | R35: 603 | S35: 604 | T35: 605 | U35: 20' | W35: 6층 | X35: 601 | Y35: 602 | Z35: 603 | AA35: 604 | AB35: 604 | AC35: 605 | AD35: 22' | AF35: 6층 | AG35: 601 | AH35: 602 | AI35: 603 | AJ35: 604 | AK35: 20' | AM35: 6층 | AN35: 601 | AO35: 602 | AP35: 603 | AQ35: 604 | AR35: 10' | AT35: 6층 | AU35: 601 | AV35: 602 | AW35: 603 | AX35: 604 | AY35: 20' | BA35: 6층 | BB35: 601 | BC35: 602 | BD35: 603 | BE35: 604 | BF35: 20' | BH35: 6층 | BI35: 601 | BJ35: 602 | BK35: 603 | BL35: 604 | BM35: 20' | BO35: 6층 | BP35: 601 | BQ35: 602 | BR35: 603 | BS35: 604 | BT35: 15'
A36: 5층 | B36: 501 | C36: 502 | D36: 503 | E36: 504 | F36: 21' | H36: 5층 | I36: 501 | J36: 502 | K36: 503 | L36: 504 | M36: 26' | O36: 5층 | P36: 501 | Q36: 502 | R36: 503 | S36: 504 | T36: 505 | U36: 21' | W36: 5층 | X36: 501 | Y36: 502 | Z36: 503 | AA36: 504 | AB36: 504 | AC36: 505 | AD36: 23' | AF36: 5층 | AG36: 501 | AH36: 502 | AI36: 503 | AJ36: 504 | AK36: 21' | AM36: 5층 | AN36: 501 | AO36: 502 | AP36: 503 | AQ36: 504 | AR36: 11' | AT36: 5층 | AU36: 501 | AV36: 502 | AW36: 503 | AX36: 504 | AY36: 21' | BA36: 5층 | BB36: 501 | BC36: 502 | BD36: 503 | BE36: 504 | BF36: 21' | BH36: 5층 | BI36: 501 | BJ36: 502 | BK36: 503 | BL36: 504 | BM36: 21' | BO36: 5층 | BP36: 501 | BQ36: 502 | BR36: 503 | BS36: 504 | BT36: 16'
A37: 4층 | B37: 401 | C37: 402 | D37: 403 | E37: 404 | F37: 22' | H37: 4층 | I37: 401 | J37: 402 | K37: 403 | L37: 404 | M37: 27' | O37: 4층 | P37: 401 | Q37: 402 | R37: 403 | S37: 404 | T37: 405 | U37: 22' | W37: 4층 | X37: 401 | Y37: 402 | Z37: 403 | AA37: 404 | AB37: 404 | AC37: 405 | AD37: 24' | AF37: 4층 | AG37: 401 | AH37: 402 | AI37: 403 | AJ37: 404 | AK37: 22' | AM37: 4층 | AN37: 401 | AO37: 402 | AP37: 403 | AQ37: 404 | AR37: 12' | AT37: 4층 | AU37: 401 | AV37: 402 | AW37: 403 | AX37: 404 | AY37: 22' | BA37: 4층 | BB37: 401 | BC37: 402 | BD37: 403 | BE37: 404 | BF37: 22' | BH37: 4층 | BI37: 401 | BJ37: 402 | BK37: 403 | BL37: 404 | BM37: 22' | BO37: 4층 | BP37: 401 | BQ37: 402 | BR37: 403 | BS37: 404 | BT37: 17'
... A39: 2층 | B39: 201 | C39: 202 | D39: 203 | E39: 204 | F39: 24' | H39: 2층 | I39: 201 | J39: 202 | K39: 203 | L39: 204 | M39: 29' | O39: 2층 | P39: 201 | Q39: 202 | R39: 203 | S39: 204 | T39: 205 | U39: 24' | W39: 2층 | X39: 201 | Y39: 202 | Z39: 203 | AA39: 204 | AB39: 204 | AC39: 205 | AD39: 26' | AF39: 2층 | AG39: 201 | AH39: 202 | AI39: 203 | AJ39: 204 | AK39: 24' | AM39: 2층 | AN39: 201 | AO39: 202 | AP39: 203 | AQ39: 204 | AR39: 14' | AT39: 2층 | AU39: 201 | AV39: 202 | AW39: 203 | AX39: 204 | AY39: 24' | BA39: 2층 | BB39: 201 | BC39: 202 | BD39: 203 | BE39: 204 | BF39: 24' | BH39: 2층 | BI39: 201 | BJ39: 202 | BK39: 203 | BL39: 204 | BM39: 24' | BO39: 2층 | BP39: 201 | BQ39: 202 | BR39: 203 | BS39: 204 | BT39: 19'
A40: 1층 | F40: 25' | H40: 1층 | M40: 30' | O40: 1층 | P40: 101 | Q40: 1302 | R40: 103 | S40: 104 | T40: 105 | U40: 25' | W40: 1층 | AD40: 27' | AF40: 1층 | AK40: 25' | AM40: 1층 | AN40: 101 | AO40: 102 | AP40: 103 | AQ40: 104 | AR40: 15' | AT40: 1층 | AY40: 25' | BA40: 1층 | BF40: 25' | BH40: 1층 | BM40: 25' | BO40: 1층 | BP40: 101 | BQ40: 102 | BR40: 103 | BS40: 104 | BT40: 20'
A41: B1 | H41: B1 | O41: B1 | W41: B1 | AF41: B1 | AM41: B1 | AT41: B1 | BA41: B1 | BH41: B1 | BO41: B1
B42: 1 | C42: 2 | D42: 3 | E42: 4 | I42: 1 | J42: 2 | K42: 3 | L42: 4 | P42: 1 | Q42: 2 | R42: 3 | S42: 4 | T42: 5 | X42: 1 | Y42: 2 | Z42: 3 | AA42: 4 | AB42: 5 | AC42: 6 | AG42: 1 | AH42: 2 | AI42: 3 | AJ42: 4 | AN42: 1 | AO42: 2 | AP42: 3 | AQ42: 4 | AU42: 1 | AV42: 2 | AW42: 3 | AX42: 4 | BB42: 1 | BC42: 2 | BD42: 3 | BE42: 4 | BI42: 1 | BJ42: 2 | BK42: 3 | BL42: 4 | BP42: 1 | BQ42: 2 | BR42: 3 | BS42: 4
B43: 84A | C43: 84A | D43: 84A | E43: 84A | I43: 59B | J43: 84A | K43: 84A | L43: 84A | P43: 104 | Q43: 104 | R43: 84B | S43: 84B | T43: 84B | X43: 84C | Y43: 84C | Z43: 84C | AA43: 84C | AB43: 84C | AC43: 84C | AG43: 49A | AH43: 49A | AI43: 49A | AJ43: 49A | AN43: 84A | AO43: 84A | AP43: 84A | AQ43: 84A | AU43: 84A | AV43: 84A | AW43: 84A | AX43: 84A | BB43: 84A | BC43: 84A | BD43: 84A | BE43: 84A | BI43: 84A | BJ43: 84A | BK43: 84A | BL43: 84A | BP43: 49A | BQ43: 49A | BR43: 49A | BS43: 49A
B44: 24 | C44: 24 | D44: 24 | E44: 24 | I44: 29 | J44: 29 | K44: 29 | L44: 29 | P44: 25 | Q44: 25 | R44: 25 | S44: 25 | T44: 25 | X44: 26 | Y44: 26 | Z44: 25 | AA44: 24 | AB44: 24 | AC44: 24 | AG44: 24 | AH44: 24 | AI44: 24 | AJ44: 24 | AN44: 15 | AO44: 15 | AP44: 15 | AQ44: 15 | AU44: 24 | AV44: 24 | AW44: 24 | AX44: 24 | BB44: 24 | BC44: 24 | BD44: 19 | BE44: 19 | BI44: 24 | BJ44: 24 | BK44: 24 | BL44: 24 | BP44: 20 | BQ44: 20 | BR44: 20 | BS44: 20
B46: =SUM(B44:E44) | I46: =SUM(I44:L44) | P46: =SUM(P44:T44) | X46: =SUM(X44:AC44) | AG46: =SUM(AG44:AJ44) | AN46: =SUM(AN44:AQ44) | AU46: =SUM(AU44:AX44) | BB46: =SUM(BB44:BE44) | BI46: =SUM(BI44:BL44) | BP46: =SUM(BP44:BS44)
B62: NO | C62: 배관명
B63: 1 | C63: 주방
B64: 2 | C64: 세탁
...

Sheet 3.이상배관LIST_입상관
A1: ■ 입상관 이상배관 LIST | J1: 입상관
A2: =입력창!B4 | J2: =입력창!B5
A3: NO | B3: 점검일 | C3: 동명 | D3: 호수 (라인) | E3: 배관명 | F3: 이상배관 이미지 | G3: 이상위치 | H3: 이상소견 | I3: 보고일 | J3: 비 고 | L3: 검사자
A19: 16
A20: 17
A21: 18
A22: 19
A23: 20
A24: 21

Sheet 1.작업현황_세대매립관
A1: ■ 세대매립관 작업현황 | AG1: 세대매립관 | BP1: 세대매립관
A2: =+입력창!B4
AF4: 1 | AG4: 2 | AH4: 3 | AI4: 4 | AJ4: 5 | BO4: 1 | BP4: 2 | BQ4: 3 | BR4: 4 | BS4: 5
AF5: =+입력창!S8 | AG5: =+입력창!T8 | AH5: =+입력창!U8 | AI5: =+입력창!V8 | AJ5: =+입력창!W8 | BO5: =+입력창!S8 | BP5: =+입력창!T8 | BQ5: =+입력창!U8 | BR5: =+입력창!V8 | BS5: =+입력창!W8
B8: 101동 | I8: 102동 | P8: 103동 | X8: 104동 | AG8: 105동 | AN8: 106동 | AU8: 107동 | BB8: 108동 | BI8: 109동 | BP8: 110동
H11: 30층 | I11: 3001 | J11: 3002 | K11: 3003 | L11: 3004
H12: 29층 | I12: 2901 | J12: 2902 | K12: 2903 | L12: 2904
H13: 28층 | I13: 2801 | J13: 2802 | K13: 2803 | L13: 2804
H14: 27층 | I14: 2701 | J14: 2702 | K14: 2703 | L14: 2704 | W14: 27층 | X14: 2701 | Y14: 2702
H15: 26층 | I15: 2601 | J15: 2602 | K15: 2603 | L15: 2604 | W15: 26층 | X15: 2601 | Y15: 2602 | Z15: 2603
A16: 25층 | B16: 2501 | C16: 2502 | D16: 2503 | E16: 2504 | H16: 25층 | I16: 2501 | J16: 2502 | K16: 2503 | L16: 2504 | O16: 25층 | P16: 2501 | Q16: 2502 | R16: 2503 | S16: 2504 | T16: 2505 | W16: 25층 | X16: 2501 | Y16: 2502 | Z16: 2503 | AA16: 2504 | AB16: 2504 | AC16: 2505 | AF16: 25층 | AG16: 2501 | AH16: 2502 | AI16: 2503 | AJ16: 2504 | AT16: 25층 | AU16: 2501 | AV16: 2502 | AW16: 2503 | AX16: 2504 | BA16: 25층 | BB16: 2501 | BC16: 2502 | BH16: 25층 | BI16: 2501 | BJ16: 2502 | BK16: 2503 | BL16: 2504
A17: 24층 | B17: 2401 | C17: 2402 | D17: 2403 | E17: 2404 | H17: 24층 | I17: 2401 | J17: 2402 | K17: 2403 | L17: 2404 | O17: 24층 | P17: 2401 | Q17: 2402 | R17: 2403 | S17: 2404 | T17: 2405 | W17: 24층 | X17: 2401 | Y17: 2402 | Z17: 2403 | AA17: 2404 | AB17: 2404 | AC17: 2405 | AF17: 24층 | AG17: 2401 | AH17: 2402 | AI17: 2403 | AJ17: 2404 | AT17: 24층 | AU17: 2401 | AV17: 2402 | AW17: 2403 | AX17: 2404 | BA17: 24층 | BB17: 2401 | BC17: 2402 | BH17: 24층 | BI17: 2401 | BJ17: 2402 | BK17: 2403 | BL17: 2404
A18: 23층 | B18: 2301 | C18: 2302 | D18: 2303 | E18: 2304 | H18: 23층 | I18: 2301 | J18: 2302 | K18: 2303 | L18: 2304 | O18: 23층 | P18: 2301 | Q18: 2302 | R18: 2303 | S18: 2304 | T18: 2305 | W18: 23층 | X18: 2301 | Y18: 2302 | Z18: 2303 | AA18: 2304 | AB18: 2304 | AC18: 2305 | AF18: 23층 | AG18: 2301 | AH18: 2302 | AI18: 2303 | AJ18: 2304 | AT18: 23층 | AU18: 2301 | AV18: 2302 | AW18: 2303 | AX18: 2304 | BA18: 23층 | BB18: 2301 | BC18: 2302 | BH18: 23층 | BI18: 2301 | BJ18: 2302 | BK18: 2303 | BL18: 2304
A19: 22층 | B19: 2201 | C19: 2202 | D19: 2203 | E19: 2204 | H19: 22층 | I19: 2201 | J19: 2202 | K19: 2203 | L19: 2204 | O19: 22층 | P19: 2201 | Q19: 2202 | R19: 2203 | S19: 2204 | T19: 2205 | W19: 22층 | X19: 2201 | Y19: 2202 | Z19: 2203 | AA19: 2204 | AB19: 2204 | AC19: 2205 | AF19: 22층 | AG19: 2201 | AH19: 2202 | AI19: 2203 | AJ19: 2204 | AT19: 22층 | AU19: 2201 | AV19: 2202 | AW19: 2203 | AX19: 2204 | BA19: 22층 | BB19: 2201 | BC19: 2202 | BH19: 22층 | BI19: 2201 | BJ19: 2202 | BK19: 2203 | BL19: 2204
A20: 21층 | B20: 2101 | C20: 2102 | D20: 2103 | E20: 2104 | H20: 21층 | I20: 2101 | J20: 2102 | K20: 2103 | L20: 2104 | O20: 21층 | P20: 2101 | Q20: 2102 | R20: 2103 | S20: 2104 | T20: 2105 | W20: 21층 | X20: 2101 | Y20: 2102 | Z20: 2103 | AA20: 2104 | AB20: 2104 | AC20: 2105 | AF20: 21층 | AG20: 2101 | AH20: 2102 | AI20: 2103 | AJ20: 2104 | AT20: 21층 | AU20: 2101 | AV20: 2102 | AW20: 2103 | AX20: 2104 | BA20: 21층 | BB20: 2101 | BC20: 2102 | BH20: 21층 | BI20: 2101 | BJ20: 2102 | BK20: 2103 | BL20: 2104
A21: 20층 | B21: 2001 | C21: 2002 | D21: 2003 | E21: 2004 | H21: 20층 | I21: 2001 | J21: 2002 | K21: 2003 | L21: 2004 | O21: 20층 | P21: 2001 | Q21: 2002 | R21: 2003 | S21: 2004 | T21: 2005 | W21: 20층 | X21: 2001 | Y21: 2002 | Z21: 2003 | AA21: 2004 | AB21: 2004 | AC21: 2005 | AF21: 20층 | AG21: 2001 | AH21: 2002 | AI21: 2003 | AJ21: 2004 | AT21: 20층 | AU21: 2001 | AV21: 2002 | AW21: 2003 | AX21: 2004 | BA21: 20층 | BB21: 2001 | BC21: 2002 | BD21: 2003 | BE21: 2004 | BH21: 20층 | BI21: 2001 | BJ21: 2002 | BK21: 2003 | BL21: 2004 | BO21: 20층 | BP21: 2001 | BQ21: 2002 | BR21: 2003 | BS21: 2004
A22: 19층 | B22: 1901 | C22: 1902 | D22: 1903 | E22: 1904 | H22: 19층 | I22: 1901 | J22: 1902 | K22: 1903 | L22: 1904 | O22: 19층 | P22: 1901 | Q22: 1902 | R22: 1903 | S22: 1904 | T22: 1905 | W22: 19층 | X22: 1901 | Y22: 1902 | Z22: 1903 | AA22: 1904 | AB22: 1904 | AC22: 1905 | AF22: 19층 | AG22: 1901 | AH22: 1902 | AI22: 1903 | AJ22: 1904 | AT22: 19층 | AU22: 1901 | AV22: 1902 | AW22: 1903 | AX22: 1904 | BA22: 19층 | BB22: 1901 | BC22: 1902 | BD22: 1903 | BE22: 1904 | BH22: 19층 | BI22: 1901 | BJ22: 1902 | BK22: 1903 | BL22: 1904 | BO22: 19층 | BP22: 1901 | BQ22: 1902 | BR22: 1903 | BS22: 1904
A23: 18층 | B23: 1801 | C23: 1802 | D23: 1803 | E23: 1804 | H23: 18층 | I23: 1801 | J23: 1802 | K23: 1803 | L23: 1804 | O23: 18층 | P23: 1801 | Q23: 1802 | R23: 1803 | S23: 1804 | T23: 1805 | W23: 18층 | X23: 1801 | Y23: 1802 | Z23: 1803 | AA23: 1804 | AB23: 1804 | AC23: 1805 | AF23: 18층 | AG23: 1801 | AH23: 1802 | AI23: 1803 | AJ23: 1804 | AT23: 18층 | AU23: 1801 | AV23: 1802 | AW23: 1803 | AX23: 1804 | BA23: 18층 | BB23: 1801 | BC23: 1802 | BD23: 1803 | BE23: 1804 | BH23: 18층 | BI23: 1801 | BJ23: 1802 | BK23: 1803 | BL23: 1804 | BO23: 18층 | BP23: 1801 | BQ23: 1802 | BR23: 1803 | BS23: 1804
A24: 17층 | B24: 1701 | C24: 1702 | D24: 1703 | E24: 1704 | H24: 17층 | I24: 1701 | J24: 1702 | K24: 1703 | L24: 1704 | O24: 17층 | P24: 1701 | Q24: 1702 | R24: 1703 | S24: 1704 | T24: 1705 | W24: 17층 | X24: 1701 | Y24: 1702 | Z24: 1703 | AA24: 1704 | AB24: 1704 | AC24: 1705 | AF24: 17층 | AG24: 1701 | AH24: 1702 | AI24: 1703 | AJ24: 1704 | AT24: 17층 | AU24: 1701 | AV24: 1702 | AW24: 1703 | AX24: 1704 | BA24: 17층 | BB24: 1701 | BC24: 1702 | BD24: 1703 | BE24: 1704 | BH24: 17층 | BI24: 1701 | BJ24: 1702 | BK24: 1703 | BL24: 1704 | BO24: 17층 | BP24: 1701 | BQ24: 1702 | BR24: 1703 | BS24: 1704
A25: 16층 | B25: 1601 | C25: 1602 | D25: 1603 | E25: 1604 | H25: 16층 | I25: 1601 | J25: 1602 | K25: 1603 | L25: 1604 | O25: 16층 | P25: 1601 | Q25: 1602 | R25: 1603 | S25: 1604 | T25: 1605 | W25: 16층 | X25: 1601 | Y25: 1602 | Z25: 1603 | AA25: 1604 | AB25: 1604 | AC25: 1605 | AF25: 16층 | AG25: 1601 | AH25: 1602 | AI25: 1603 | AJ25: 1604 | AT25: 16층 | AU25: 1601 | AV25: 1602 | AW25: 1603 | AX25: 1604 | BA25: 16층 | BB25: 1601 | BC25: 1602 | BD25: 1603 | BE25: 1604 | BH25: 16층 | BI25: 1601 | BJ25: 1602 | BK25: 1603 | BL25: 1604 | BO25: 16층 | BP25: 1601 | BQ25: 1602 | BR25: 1603 | BS25: 1604
A26: 15층 | B26: 1501 | C26: 1502 | D26: 1503 | E26: 1504 | H26: 15층 | I26: 1501 | J26: 1502 | K26: 1503 | L26: 1504 | O26: 15층 | P26: 1501 | Q26: 1502 | R26: 1503 | S26: 1504 | T26: 1505 | W26: 15층 | X26: 1501 | Y26: 1502 | Z26: 1503 | AA26: 1504 | AB26: 1504 | AC26: 1505 | AF26: 15층 | AG26: 1501 | AH26: 1502 | AI26: 1503 | AJ26: 1504 | AM26: 15층 | AN26: 1501 | AO26: 1502 | AP26: 1503 | AQ26: 1504 | AT26: 15층 | AU26: 1501 | AV26: 1502 | AW26: 1503 | AX26: 1504 | BA26: 15층 | BB26: 1501 | BC26: 1502 | BD26: 1503 | BE26: 1504 | BH26: 15층 | BI26: 1501 | BJ26: 1502 | BK26: 1503 | BL26: 1504 | BO26: 15층 | BP26: 1501 | BQ26: 1502 | BR26: 1503 | BS26: 1504
A27: 14층 | B27: 1401 | C27: 1402 | D27: 1403 | E27: 1404 | H27: 14층 | I27: 1401 | J27: 1402 | K27: 1403 | L27: 1404 | O27: 14층 | P27: 1401 | Q27: 1402 | R27: 1403 | S27: 1404 | T27: 1405 | W27: 14층 | X27: 1401 | Y27: 1402 | Z27: 1403 | AA27: 1404 | AB27: 1404 | AC27: 1405 | AF27: 14층 | AG27: 1401 | AH27: 1402 | AI27: 1403 | AJ27: 1404 | AM27: 14층 | AN27: 1401 | AO27: 1402 | AP27: 1403 | AQ27: 1404 | AT27: 14층 | AU27: 1401 | AV27: 1402 | AW27: 1403 | AX27: 1404 | BA27: 14층 | BB27: 1401 | BC27: 1402 | BD27: 1403 | BE27: 1404 | BH27: 14층 | BI27: 1401 | BJ27: 1402 | BK27: 1403 | BL27: 1404 | BO27: 14층 | BP27: 1401 | BQ27: 1402 | BR27: 1403 | BS27: 1404
A28: 13층 | B28: 1301 | C28: 1302 | D28: 1303 | E28: 1304 | H28: 13층 | I28: 1301 | J28: 1302 | K28: 1303 | L28: 1304 | O28: 13층 | P28: 1301 | Q28: 1302 | R28: 1303 | S28: 1304 | T28: 1305 | W28: 13층 | X28: 1301 | Y28: 1302 | Z28: 1303 | AA28: 1304 | AB28: 1304 | AC28: 1305 | AF28: 13층 | AG28: 1301 | AH28: 1302 | AI28: 1303 | AJ28: 1304 | AM28: 13층 | AN28: 1301 | AO28: 1302 | AP28: 1303 | AQ28: 1304 | AT28: 13층 | AU28: 1301 | AV28: 1302 | AW28: 1303 | AX28: 1304 | BA28: 13층 | BB28: 1301 | BC28: 1302 | BD28: 1303 | BE28: 1304 | BH28: 13층 | BI28: 1301 | BJ28: 1302 | BK28: 1303 | BL28: 1304 | BO28: 13층 | BP28: 1301 | BQ28: 1302 | BR28: 1303 | BS28: 1304
A29: 12층 | B29: 1201 | C29: 1202 | D29: 1203 | E29: 1204 | H29: 12층 | I29: 1201 | J29: 1202 | K29: 1203 | L29: 1204 | O29: 12층 | P29: 1201 | Q29: 1202 | R29: 1203 | S29: 1204 | T29: 1205 | W29: 12층 | X29: 1201 | Y29: 1202 | Z29: 1203 | AA29: 1204 | AB29: 1204 | AC29: 1205 | AF29: 12층 | AG29: 1201 | AH29: 1202 | AI29: 1203 | AJ29: 1204 | AM29: 12층 | AN29: 1201 | AO29: 1202 | AP29: 1203 | AQ29: 1204 | AT29: 12층 | AU29: 1201 | AV29: 1202 | AW29: 1203 | AX29: 1204 | BA29: 12층 | BB29: 1201 | BC29: 1202 | BD29: 1203 | BE29: 1204 | BH29: 12층 | BI29: 1201 | BJ29: 1202 | BK29: 1203 | BL29: 1204 | BO29: 12층 | BP29: 1201 | BQ29: 1202 | BR29: 1203 | BS29: 1204
A30: 11층 | B30: 1101 | C30: 1102 | D30: 1103 | E30: 1104 | H30: 11층 | I30: 1101 | J30: 1102 | K30: 1103 | L30: 1104 | O30: 11층 | P30: 1101 | Q30: 1102 | R30: 1103 | S30: 1104 | T30: 1105 | W30: 11층 | X30: 1101 | Y30: 1102 | Z30: 1103 | AA30: 1104 | AB30: 1104 | AC30: 1105 | AF30: 11층 | AG30: 1101 | AH30: 1102 | AI30: 1103 | AJ30: 1104 | AM30: 11층 | AN30: 1101 | AO30: 1102 | AP30: 1103 | AQ30: 1104 | AT30: 11층 | AU30: 1101 | AV30: 1102 | AW30: 1103 | AX30: 1104 | BA30: 11층 | BB30: 1101 | BC30: 1102 | BD30: 1103 | BE30: 1104 | BH30: 11층 | BI30: 1101 | BJ30: 1102 | BK30: 1103 | BL30: 1104 | BO30: 11층 | BP30: 1101 | BQ30: 1102 | BR30: 1103 | BS30: 1104
A31: 10층 | B31: 1001 | C31: 1002 | D31: 1003 | E31: 1004 | H31: 10층 | I31: 1001 | J31: 1002 | K31: 1003 | L31: 1004 | O31: 10층 | P31: 1001 | Q31: 1002 | R31: 1003 | S31: 1004 | T31: 1005 | W31: 10층 | X31: 1001 | Y31: 1002 | Z31: 1003 | AA31: 1004 | AB31: 1004 | AC31: 1005 | AF31: 10층 | AG31: 1001 | AH31: 1002 | AI31: 1003 | AJ31: 1004 | AM31: 10층 | AN31: 1001 | AO31: 1002 | AP31: 1003 | AQ31: 1004 | AT31: 10층 | AU31: 1001 | AV31: 1002 | AW31: 1003 | AX31: 1004 | BA31: 10층 | BB31: 1001 | BC31: 1002 | BD31: 1003 | BE31: 1004 | BH31: 10층 | BI31: 1001 | BJ31: 1002 | BK31: 1003 | BL31: 1004 | BO31: 10층 | BP31: 1001 | BQ31: 1002 | BR31: 1003 | BS31: 1004
A32: 9층 | B32: 901 | C32: 902 | D32: 903 | E32: 904 | H32: 9층 | I32: 901 | J32: 902 | K32: 903 | L32: 904 | O32: 9층 | P32: 901 | Q32: 902 | R32: 903 | S32: 904 | T32: 905 | W32: 9층 | X32: 901 | Y32: 902 | Z32: 903 | AA32: 904 | AB32: 904 | AC32: 905 | AF32: 9층 | AG32: 901 | AH32: 902 | AI32: 903 | AJ32: 904 | AM32: 9층 | AN32: 901 | AO32: 902 | AP32: 903 | AQ32: 904 | AT32: 9층 | AU32: 901 | AV32: 902 | AW32: 903 | AX32: 904 | BA32: 9층 | BB32: 901 | BC32: 902 | BD32: 903 | BE32: 904 | BH32: 9층 | BI32: 901 | BJ32: 902 | BK32: 903 | BL32: 904 | BO32: 9층 | BP32: 901 | BQ32: 902 | BR32: 903 | BS32: 904
A33: 8층 | B33: 801 | C33: 802 | D33: 803 | E33: 804 | H33: 8층 | I33: 801 | J33: 802 | K33: 803 | L33: 804 | O33: 8층 | P33: 801 | Q33: 802 | R33: 803 | S33: 804 | T33: 805 | W33: 8층 | X33: 801 | Y33: 802 | Z33: 803 | AA33: 804 | AB33: 804 | AF33: 8층 | AG33: 801 | AH33: 802 | AI33: 803 | AJ33: 804 | AM33: 8층 | AN33: 801 | AO33: 802 | AP33: 803 | AQ33: 804 | AT33: 8층 | AU33: 801 | AV33: 802 | AW33: 803 | AX33: 804 | BA33: 8층 | BB33: 801 | BC33: 802 | BD33: 803 | BE33: 804 | BH33: 8층 | BI33: 801 | BJ33: 802 | BK33: 803 | BL33: 804 | BO33: 8층 | BP33: 801 | BQ33: 802 | BR33: 803 | BS33: 804
A34: 7층 | B34: 701 | C34: 702 | D34: 703 | E34: 704 | H34: 7층 | I34: 701 | J34: 702 | K34: 703 | L34: 704 | O34: 7층 | P34: 701 | Q34: 702 | R34: 703 | S34: 704 | T34: 705 | W34: 7층 | X34: 701 | Y34: 702 | Z34: 703 | AA34: 704 | AB34: 704 | AC34: 705 | AF34: 7층 | AG34: 701 | AH34: 702 | AI34: 703 | AJ34: 704 | AM34: 7층 | AN34: 701 | AO34: 702 | AP34: 703 | AQ34: 704 | AT34: 7층 | AU34: 701 | AV34: 702 | AW34: 703 | AX34: 704 | BA34: 7층 | BB34: 701 | BC34: 702 | BD34: 703 | BE34: 704 | BH34: 7층 | BI34: 701 | BJ34: 702 | BK34: 703 | BL34: 704 | BO34: 7층 | BP34: 701 | BQ34: 702 | BR34: 703 | BS34: 704
A35: 6층 | B35: 601 | C35: 602 | D35: 603 | E35: 604 | H35: 6층 | I35: 601 | J35: 602 | K35: 603 | L35: 604 | O35: 6층 | P35: 601 | Q35: 602 | R35: 603 | S35: 604 | T35: 605 | W35: 6층 | X35: 601 | Y35: 602 | Z35: 603 | AA35: 604 | AB35: 604 | AC35: 605 | AF35: 6층 | AG35: 601 | AH35: 602 | AI35: 603 | AJ35: 604 | AM35: 6층 | AN35: 601 | AO35: 602 | AP35: 603 | AQ35: 604 | AT35: 6층 | AU35: 601 | AV35: 602 | AW35: 603 | AX35: 604 | BA35: 6층 | BB35: 601 | BC35: 602 | BD35: 603 | BE35: 604 | BH35: 6층 | BI35: 601 | BJ35: 602 | BK35: 603 | BL35: 604 | BO35: 6층 | BP35: 601 | BQ35: 602 | BR35: 603 | BS35: 604
A36: 5층 | B36: 501 | C36: 502 | D36: 503 | E36: 504 | H36: 5층 | I36: 501 | J36: 502 | K36: 503 | L36: 504 | O36: 5층 | P36: 501 | Q36: 502 | R36: 503 | S36: 504 | T36: 505 | W36: 5층 | X36: 501 | Y36: 502 | Z36: 503 | AA36: 504 | AB36: 504 | AC36: 505 | AF36: 5층 | AG36: 501 | AH36: 502 | AI36: 503 | AJ36: 504 | AM36: 5층 | AN36: 501 | AO36: 502 | AP36: 503 | AQ36: 504 | AT36: 5층 | AU36: 501 | AV36: 502 | AW36: 503 | AX36: 504 | BA36: 5층 | BB36: 501 | BC36: 502 | BD36: 503 | BE36: 504 | BH36: 5층 | BI36: 501 | BJ36: 502 | BK36: 503 | BL36: 504 | BO36: 5층 | BP36: 501 | BQ36: 502 | BR36: 503 | BS36: 504
A37: 4층 | B37: 401 | C37: 402 | D37: 403 | E37: 404 | H37: 4층 | I37: 401 | J37: 402 | K37: 403 | L37: 404 | O37: 4층 | P37: 401 | Q37: 402 | R37: 403 | S37: 404 | T37: 405 | W37: 4층 | X37: 401 | Y37: 402 | Z37: 403 | AA37: 404 | AB37: 404 | AC37: 405 | AF37: 4층 | AG37: 401 | AH37: 402 | AI37: 403 | AJ37: 404 | AM37: 4층 | AN37: 401 | AO37: 402 | AP37: 403 | AQ37: 404 | AT37: 4층 | AU37: 401 | AV37: 402 | AW37: 403 | AX37: 404 | BA37: 4층 | BB37: 401 | BC37: 402 | BD37: 403 | BE37: 404 | BH37: 4층 | BI37: 401 | BJ37: 402 | BK37: 403 | BL37: 404 | BO37: 4층 | BP37: 401 | BQ37: 402 | BR37: 403 | BS37: 404
A38: 3층 | B38: 301 | C38: 302 | D38: 303 | E38: 304 | H38: 3층 | I38: 301 | J38: 302 | K38: 303 | L38: 304 | O38: 3층 | P38: 301 | Q38: 302 | R38: 303 | S38: 304 | T38: 305 | W38: 3층 | X38: 301 | Y38: 302 | Z38: 303 | AA38: 304 | AB38: 304 | AC38: 305 | AF38: 3층 | AG38: 301 | AH38: 302 | AI38: 303 | AJ38: 304 | AM38: 3층 | AN38: 301 | AO38: 302 | AP38: 303 | AQ38: 304 | AT38: 3층 | AU38: 301 | AV38: 302 | AW38: 303 | AX38: 304 | BA38: 3층 | BB38: 301 | BC38: 302 | BD38: 303 | BE38: 304 | BH38: 3층 | BI38: 301 | BJ38: 302 | BK38: 303 | BL38: 304 | BO38: 3층 | BP38: 301 | BQ38: 302 | BR38: 303 | BS38: 304
A39: 2층 | B39: 201 | C39: 202 | D39: 203 | E39: 204 | H39: 2층 | I39: 201 | J39: 202 | K39: 203 | L39: 204 | O39: 2층 | P39: 201 | Q39: 202 | R39: 203 | S39: 204 | T39: 205 | W39: 2층 | X39: 201 | Y39: 202 | Z39: 203 | AA39: 204 | AB39: 204 | AC39: 205 | AF39: 2층 | AG39: 201 | AH39: 202 | AI39: 203 | AJ39: 204 | AM39: 2층 | AN39: 201 | AO39: 202 | AP39: 203 | AQ39: 204 | AT39: 2층 | AU39: 201 | AV39: 202 | AW39: 203 | AX39: 204 | BA39: 2층 | BB39: 201 | BC39: 202 | BD39: 203 | BE39: 204 | BH39: 2층 | BI39: 201 | BJ39: 202 | BK39: 203 | BL39: 204 | BO39: 2층 | BP39: 201 | BQ39: 202 | BR39: 203 | BS39: 204
A40: 1층 | H40: 1층 | O40: 1층 | P40: 101 | Q40: 102 | R40: 103 | S40: 104 | T40: 105 | W40: 1층 | AF40: 1층 | AM40: 1층 | AN40: 101 | AO40: 102 | AP40: 103 | AQ40: 104 | AT40: 1층 | BA40: 1층 | BH40: 1층 | BO40: 1층 | BP40: 101 | BQ40: 102 | BR40: 103 | BS40: 104
A41: B1 | H41: B1 | O41: B1 | W41: B1 | AF41: B1 | AM41: B1 | AT41: B1 | BA41: B1 | BH41: B1 | BO41: B1
B42: 1 | C42: 2 | D42: 3 | E42: 4 | I42: 1 | J42: 2 | K42: 3 | L42: 4 | P42: 1 | Q42: 2 | R42: 3 | S42: 4 | T42: 5 | X42: 1 | Y42: 2 | Z42: 3 | AA42: 4 | AB42: 5 | AC42: 6 | AG42: 1 | AH42: 2 | AI42: 3 | AJ42: 4 | AN42: 1 | AO42: 2 | AP42: 3 | AQ42: 4 | AU42: 1 | AV42: 2 | AW42: 3 | AX42: 4 | BB42: 1 | BC42: 2 | BD42: 3 | BE42: 4 | BI42: 1 | BJ42: 2 | BK42: 3 | BL42: 4 | BP42: 1 | BQ42: 2 | BR42: 3 | BS42: 4
B43: 84A | C43: 84A | D43: 84A | E43: 84A | I43: 59B | J43: 84A | K43: 84A | L43: 84A | P43: 104 | Q43: 104 | R43: 84B | S43: 84B | T43: 84B | X43: 84C | Y43: 84C | Z43: 84C | AA43: 84C | AB43: 84C | AC43: 84C | AG43: 49A | AH43: 49A | AI43: 49A | AJ43: 49A | AN43: 84A | AO43: 84A | AP43: 84A | AQ43: 84A | AU43: 84A | AV43: 84A | AW43: 84A | AX43: 84A | BB43: 84A | BC43: 84A | BD43: 84A | BE43: 84A | BI43: 84A | BJ43: 84A | BK43: 84A | BL43: 84A | BP43: 49A | BQ43: 49A | BR43: 49A | BS43: 49A
B44: 24 | C44: 24 | D44: 24 | E44: 24 | I44: 29 | J44: 29 | K44: 29 | L44: 29 | P44: 25 | Q44: 25 | R44: 25 | S44: 25 | T44: 25 | X44: 26 | Y44: 26 | Z44: 25 | AA44: 24 | AB44: 24 | AC44: 24 | AG44: 24 | AH44: 24 | AI44: 24 | AJ44: 24 | AN44: 15 | AO44: 15 | AP44: 15 | AQ44: 15 | AU44: 24 | AV44: 24 | AW44: 24 | AX44: 24 | BB44: 24 | BC44: 24 | BD44: 19 | BE44: 19 | BI44: 24 | BJ44: 24 | BK44: 24 | BL44: 24 | BP44: 20 | BQ44: 20 | BR44: 20 | BS44: 20
B45: 1/2 | C45: 1/2 | D45: 1/2 | E45: 1/2 | I45: 1/2 | J45: 1/2 | K45: 1/2 | L45: 1/2 | P45: 1/2/3 | Q45: 1/2/3 | R45: 1/2 | S45: 1/2 | T45: 1/2 | X45: 1/2 | Y45: 1/2 | Z45: 1/2 | AA45: 1/2 | AB45: 1/2 | AC45: 1/2 | AG45: 1/2 | AH45: 1/2 | AI45: 1/2 | AJ45: 1/2 | AN45: 1/2 | AO45: 1/2 | AP45: 1/2 | AQ45: 1/2 | AU45: 1/2 | AV45: 1/2 | AW45: 1/2 | AX45: 1/2 | BB45: 1/2 | BC45: 1/2 | BD45: 1/2 | BE45: 1/2 | BI45: 1/2 | BJ45: 1/2 | BK45: 1/2 | BL45: 1/2 | BP45: 1/2 | BQ45: 1/2 | BR45: 1/2 | BS45: 1/2
...

Sheet 2.이상배관위치_세대매립관
A1: ■ 세대매립관 이상위치 | AG1: 세대매립관 | BP1: 세대매립관
A2: =+입력창!B4
AF4: 1 | AG4: 2 | AH4: 3 | AI4: 4 | AJ4: 5 | BO4: 1 | BP4: 2 | BQ4: 3 | BR4: 4 | BS4: 5
AF5: =+입력창!S8 | AG5: =+입력창!T8 | AH5: =+입력창!U8 | AI5: =+입력창!V8 | AJ5: =+입력창!W8 | BO5: =+입력창!S8 | BP5: =+입력창!T8 | BQ5: =+입력창!U8 | BR5: =+입력창!V8 | BS5: =+입력창!W8
B8: 101동 | I8: 102동 | P8: 103동 | X8: 104동 | AG8: 105동 | AN8: 106동 | AU8: 107동 | BB8: 108동 | BI8: 109동 | BP8: 110동
H11: 30층 | I11: 3001 | J11: 3002 | K11: 3003 | L11: 3004
H12: 29층 | I12: 2901 | J12: 2902 | K12: 2903 | L12: 2904
H13: 28층 | I13: 2801 | J13: 2802 | K13: 2803 | L13: 2804
H14: 27층 | I14: 2701 | J14: 2702 | K14: 2703 | L14: 2704 | W14: 27층 | X14: 2701 | Y14: 2702
H15: 26층 | I15: 2601 | J15: 2602 | K15: 2603 | L15: 2604 | W15: 26층 | X15: 2601 | Y15: 2602 | Z15: 2603
A16: 25층 | B16: 2501 | C16: 2502 | D16: 2503 | E16: 2504 | H16: 25층 | I16: 2501 | J16: 2502 | K16: 2503 | L16: 2504 | O16: 25층 | P16: 2501 | Q16: 2502 | R16: 2503 | S16: 2504 | T16: 2505 | W16: 25층 | X16: 2501 | Y16: 2502 | Z16: 2503 | AA16: 2504 | AB16: 2504 | AC16: 2505 | AF16: 25층 | AG16: 2501 | AH16: 2502 | AI16: 2503 | AJ16: 2504 | AT16: 25층 | AU16: 2501 | AV16: 2502 | AW16: 2503 | AX16: 2504 | BA16: 25층 | BB16: 2501 | BC16: 2502 | BH16: 25층 | BI16: 2501 | BJ16: 2502 | BK16: 2503 | BL16: 2504
A17: 24층 | B17: 2401 | C17: 2402 | D17: 2403 | E17: 2404 | H17: 24층 | I17: 2401 | J17: 2402 | K17: 2403 | L17: 2404 | O17: 24층 | P17: 2401 | Q17: 2402 | R17: 2403 | S17: 2404 | T17: 2405 | W17: 24층 | X17: 2401 | Y17: 2402 | Z17: 2403 | AA17: 2404 | AB17: 2404 | AC17: 2405 | AF17: 24층 | AG17: 2401 | AH17: 2402 | AI17: 2403 | AJ17: 2404 | AT17: 24층 | AU17: 2401 | AV17: 2402 | AW17: 2403 | AX17: 2404 | BA17: 24층 | BB17: 2401 | BC17: 2402 | BH17: 24층 | BI17: 2401 | BJ17: 2402 | BK17: 2403 | BL17: 2404
A18: 23층 | B18: 2301 | C18: 2302 | D18: 2303 | E18: 2304 | H18: 23층 | I18: 2301 | J18: 2302 | K18: 2303 | L18: 2304 | O18: 23층 | P18: 2301 | Q18: 2302 | R18: 2303 | S18: 2304 | T18: 2305 | W18: 23층 | X18: 2301 | Y18: 2302 | Z18: 2303 | AA18: 2304 | AB18: 2304 | AC18: 2305 | AF18: 23층 | AG18: 2301 | AH18: 2302 | AI18: 2303 | AJ18: 2304 | AT18: 23층 | AU18: 2301 | AV18: 2302 | AW18: 2303 | AX18: 2304 | BA18: 23층 | BB18: 2301 | BC18: 2302 | BH18: 23층 | BI18: 2301 | BJ18: 2302 | BK18: 2303 | BL18: 2304
A19: 22층 | B19: 2201 | C19: 2202 | D19: 2203 | E19: 2204 | H19: 22층 | I19: 2201 | J19: 2202 | K19: 2203 | L19: 2204 | O19: 22층 | P19: 2201 | Q19: 2202 | R19: 2203 | S19: 2204 | T19: 2205 | W19: 22층 | X19: 2201 | Y19: 2202 | Z19: 2203 | AA19: 2204 | AB19: 2204 | AC19: 2205 | AF19: 22층 | AG19: 2201 | AH19: 2202 | AI19: 2203 | AJ19: 2204 | AT19: 22층 | AU19: 2201 | AV19: 2202 | AW19: 2203 | AX19: 2204 | BA19: 22층 | BB19: 2201 | BC19: 2202 | BH19: 22층 | BI19: 2201 | BJ19: 2202 | BK19: 2203 | BL19: 2204
A20: 21층 | B20: 2101 | C20: 2102 | D20: 2103 | E20: 2104 | H20: 21층 | I20: 2101 | J20: 2102 | K20: 2103 | L20: 2104 | O20: 21층 | P20: 2101 | Q20: 2102 | R20: 2103 | S20: 2104 | T20: 2105 | W20: 21층 | X20: 2101 | Y20: 2102 | Z20: 2103 | AA20: 2104 | AB20: 2104 | AC20: 2105 | AF20: 21층 | AG20: 2101 | AH20: 2102 | AI20: 2103 | AJ20: 2104 | AT20: 21층 | AU20: 2101 | AV20: 2102 | AW20: 2103 | AX20: 2104 | BA20: 21층 | BB20: 2101 | BC20: 2102 | BH20: 21층 | BI20: 2101 | BJ20: 2102 | BK20: 2103 | BL20: 2104
A21: 20층 | B21: 2001 | C21: 2002 | D21: 2003 | E21: 2004 | H21: 20층 | I21: 2001 | J21: 2002 | K21: 2003 | L21: 2004 | O21: 20층 | P21: 2001 | Q21: 2002 | R21: 2003 | S21: 2004 | T21: 2005 | W21: 20층 | X21: 2001 | Y21: 2002 | Z21: 2003 | AA21: 2004 | AB21: 2004 | AC21: 2005 | AF21: 20층 | AG21: 2001 | AH21: 2002 | AI21: 2003 | AJ21: 2004 | AT21: 20층 | AU21: 2001 | AV21: 2002 | AW21: 2003 | AX21: 2004 | BA21: 20층 | BB21: 2001 | BC21: 2002 | BD21: 2003 | BE21: 2004 | BH21: 20층 | BI21: 2001 | BJ21: 2002 | BK21: 2003 | BL21: 2004 | BO21: 20층 | BP21: 2001 | BQ21: 2002 | BR21: 2003 | BS21: 2004
A22: 19층 | B22: 1901 | C22: 1902 | D22: 1903 | E22: 1904 | H22: 19층 | I22: 1901 | J22: 1902 | K22: 1903 | L22: 1904 | O22: 19층 | P22: 1901 | Q22: 1902 | R22: 1903 | S22: 1904 | T22: 1905 | W22: 19층 | X22: 1901 | Y22: 1902 | Z22: 1903 | AA22: 1904 | AB22: 1904 | AC22: 1905 | AF22: 19층 | AG22: 1901 | AH22: 1902 | AI22: 1903 | AJ22: 1904 | AT22: 19층 | AU22: 1901 | AV22: 1902 | AW22: 1903 | AX22: 1904 | BA22: 19층 | BB22: 1901 | BC22: 1902 | BD22: 1903 | BE22: 1904 | BH22: 19층 | BI22: 1901 | BJ22: 1902 | BK22: 1903 | BL22: 1904 | BO22: 19층 | BP22: 1901 | BQ22: 1902 | BR22: 1903 | BS22: 1904
A23: 18층 | B23: 1801 | C23: 1802 | D23: 1803 | E23: 1804 | H23: 18층 | I23: 1801 | J23: 1802 | K23: 1803 | L23: 1804 | O23: 18층 | P23: 1801 | Q23: 1802 | R23: 1803 | S23: 1804 | T23: 1805 | W23: 18층 | X23: 1801 | Y23: 1802 | Z23: 1803 | AA23: 1804 | AB23: 1804 | AC23: 1805 | AF23: 18층 | AG23: 1801 | AH23: 1802 | AI23: 1803 | AJ23: 1804 | AT23: 18층 | AU23: 1801 | AV23: 1802 | AW23: 1803 | AX23: 1804 | BA23: 18층 | BB23: 1801 | BC23: 1802 | BD23: 1803 | BE23: 1804 | BH23: 18층 | BI23: 1801 | BJ23: 1802 | BK23: 1803 | BL23: 1804 | BO23: 18층 | BP23: 1801 | BQ23: 1802 | BR23: 1803 | BS23: 1804
A24: 17층 | B24: 1701 | C24: 1702 | D24: 1703 | E24: 1704 | H24: 17층 | I24: 1701 | J24: 1702 | K24: 1703 | L24: 1704 | O24: 17층 | P24: 1701 | Q24: 1702 | R24: 1703 | S24: 1704 | T24: 1705 | W24: 17층 | X24: 1701 | Y24: 1702 | Z24: 1703 | AA24: 1704 | AB24: 1704 | AC24: 1705 | AF24: 17층 | AG24: 1701 | AH24: 1702 | AI24: 1703 | AJ24: 1704 | AT24: 17층 | AU24: 1701 | AV24: 1702 | AW24: 1703 | AX24: 1704 | BA24: 17층 | BB24: 1701 | BC24: 1702 | BD24: 1703 | BE24: 1704 | BH24: 17층 | BI24: 1701 | BJ24: 1702 | BK24: 1703 | BL24: 1704 | BO24: 17층 | BP24: 1701 | BQ24: 1702 | BR24: 1703 | BS24: 1704
A25: 16층 | B25: 1601 | C25: 1602 | D25: 1603 | E25: 1604 | H25: 16층 | I25: 1601 | J25: 1602 | K25: 1603 | L25: 1604 | O25: 16층 | P25: 1601 | Q25: 1602 | R25: 1603 | S25: 1604 | T25: 1605 | W25: 16층 | X25: 1601 | Y25: 1602 | Z25: 1603 | AA25: 1604 | AB25: 1604 | AC25: 1605 | AF25: 16층 | AG25: 1601 | AH25: 1602 | AI25: 1603 | AJ25: 1604 | AT25: 16층 | AU25: 1601 | AV25: 1602 | AW25: 1603 | AX25: 1604 | BA25: 16층 | BB25: 1601 | BC25: 1602 | BD25: 1603 | BE25: 1604 | BH25: 16층 | BI25: 1601 | BJ25: 1602 | BK25: 1603 | BL25: 1604 | BO25: 16층 | BP25: 1601 | BQ25: 1602 | BR25: 1603 | BS25: 1604
A26: 15층 | B26: 1501 | C26: 1502 | D26: 1503 | E26: 1504 | H26: 15층 | I26: 1501 | J26: 1502 | K26: 1503 | L26: 1504 | O26: 15층 | P26: 1501 | Q26: 1502 | R26: 1503 | S26: 1504 | T26: 1505 | W26: 15층 | X26: 1501 | Y26: 1502 | Z26: 1503 | AA26: 1504 | AB26: 1504 | AC26: 1505 | AF26: 15층 | AG26: 1501 | AH26: 1502 | AI26: 1503 | AJ26: 1504 | AM26: 15층 | AN26: 1501 | AO26: 1502 | AP26: 1503 | AQ26: 1504 | AT26: 15층 | AU26: 1501 | AV26: 1502 | AW26: 1503 | AX26: 1504 | BA26: 15층 | BB26: 1501 | BC26: 1502 | BD26: 1503 | BE26: 1504 | BH26: 15층 | BI26: 1501 | BJ26: 1502 | BK26: 1503 | BL26: 1504 | BO26: 15층 | BP26: 1501 | BQ26: 1502 | BR26: 1503 | BS26: 1504
A27: 14층 | B27: 1401 | C27: 1402 | D27: 1403 | E27: 1404 | H27: 14층 | I27: 1401 | J27: 1402 | K27: 1403 | L27: 1404 | O27: 14층 | P27: 1401 | Q27: 1402 | R27: 1403 | S27: 1404 | T27: 1405 | W27: 14층 | X27: 1401 | Y27: 1402 | Z27: 1403 | AA27: 1404 | AB27: 1404 | AC27: 1405 | AF27: 14층 | AG27: 1401 | AH27: 1402 | AI27: 1403 | AJ27: 1404 | AM27: 14층 | AN27: 1401 | AO27: 1402 | AP27: 1403 | AQ27: 1404 | AT27: 14층 | AU27: 1401 | AV27: 1402 | AW27: 1403 | AX27: 1404 | BA27: 14층 | BB27: 1401 | BC27: 1402 | BD27: 1403 | BE27: 1404 | BH27: 14층 | BI27: 1401 | BJ27: 1402 | BK27: 1403 | BL27: 1404 | BO27: 14층 | BP27: 1401 | BQ27: 1402 | BR27: 1403 | BS27: 1404
A28: 13층 | B28: 1301 | C28: 1302 | D28: 1303 | E28: 1304 | H28: 13층 | I28: 1301 | J28: 1302 | K28: 1303 | L28: 1304 | O28: 13층 | P28: 1301 | Q28: 1302 | R28: 1303 | S28: 1304 | T28: 1305 | W28: 13층 | X28: 1301 | Y28: 1302 | Z28: 1303 | AA28: 1304 | AB28: 1304 | AC28: 1305 | AF28: 13층 | AG28: 1301 | AH28: 1302 | AI28: 1303 | AJ28: 1304 | AM28: 13층 | AN28: 1301 | AO28: 1302 | AP28: 1303 | AQ28: 1304 | AT28: 13층 | AU28: 1301 | AV28: 1302 | AW28: 1303 | AX28: 1304 | BA28: 13층 | BB28: 1301 | BC28: 1302 | BD28: 1303 | BE28: 1304 | BH28: 13층 | BI28: 1301 | BJ28: 1302 | BK28: 1303 | BL28: 1304 | BO28: 13층 | BP28: 1301 | BQ28: 1302 | BR28: 1303 | BS28: 1304
A29: 12층 | B29: 1201 | C29: 1202 | D29: 1203 | E29: 1204 | H29: 12층 | I29: 1201 | J29: 1202 | K29: 1203 | L29: 1204 | O29: 12층 | P29: 1201 | Q29: 1202 | R29: 1203 | S29: 1204 | T29: 1205 | W29: 12층 | X29: 1201 | Y29: 1202 | Z29: 1203 | AA29: 1204 | AB29: 1204 | AC29: 1205 | AF29: 12층 | AG29: 1201 | AH29: 1202 | AI29: 1203 | AJ29: 1204 | AM29: 12층 | AN29: 1201 | AO29: 1202 | AP29: 1203 | AQ29: 1204 | AT29: 12층 | AU29: 1201 | AV29: 1202 | AW29: 1203 | AX29: 1204 | BA29: 12층 | BB29: 1201 | BC29: 1202 | BD29: 1203 | BE29: 1204 | BH29: 12층 | BI29: 1201 | BJ29: 1202 | BK29: 1203 | BL29: 1204 | BO29: 12층 | BP29: 1201 | BQ29: 1202 | BR29: 1203 | BS29: 1204
A30: 11층 | B30: 1101 | C30: 1102 | D30: 1103 | E30: 1104 | H30: 11층 | I30: 1101 | J30: 1102 | K30: 1103 | L30: 1104 | O30: 11층 | P30: 1101 | Q30: 1102 | R30: 1103 | S30: 1104 | T30: 903 | W30: 11층 | X30: 1101 | Y30: 1102 | Z30: 1103 | AA30: 1104 | AB30: 1104 | AC30: 1105 | AF30: 11층 | AG30: 1101 | AH30: 1102 | AI30: 1103 | AJ30: 1104 | AM30: 11층 | AN30: 1101 | AO30: 1102 | AP30: 1103 | AQ30: 1104 | AT30: 11층 | AU30: 1101 | AV30: 1102 | AW30: 1103 | AX30: 1104 | BA30: 11층 | BB30: 1101 | BC30: 1102 | BD30: 1103 | BE30: 1104 | BH30: 11층 | BI30: 1101 | BJ30: 1102 | BK30: 1103 | BL30: 1104 | BO30: 11층 | BP30: 1101 | BQ30: 1102 | BR30: 1103 | BS30: 1104
A31: 10층 | B31: 1001 | C31: 1002 | D31: 1003 | E31: 1004 | H31: 10층 | I31: 1001 | J31: 1002 | K31: 1003 | L31: 1004 | O31: 10층 | P31: 1001 | Q31: 1002 | R31: 1003 | S31: 1004 | T31: 1005 | W31: 10층 | X31: 1001 | Y31: 1002 | Z31: 1003 | AA31: 1004 | AB31: 1004 | AC31: 1005 | AF31: 10층 | AG31: 1001 | AH31: 1002 | AI31: 1003 | AJ31: 1004 | AM31: 10층 | AN31: 1001 | AO31: 1002 | AP31: 1003 | AQ31: 1004 | AT31: 10층 | AU31: 1001 | AV31: 1002 | AW31: 1003 | AX31: 1004 | BA31: 10층 | BB31: 1001 | BC31: 1002 | BD31: 1003 | BE31: 1004 | BH31: 10층 | BI31: 1001 | BJ31: 1002 | BK31: 1003 | BL31: 1004 | BO31: 10층 | BP31: 1001 | BQ31: 1002 | BR31: 1003 | BS31: 1004
A32: 9층 | B32: 901 | C32: 902 | D32: 903 | E32: 904 | H32: 9층 | I32: 901 | J32: 902 | K32: 903 | L32: 904 | O32: 9층 | P32: 901 | Q32: 902 | R32: 903 | S32: 904 | T32: 905 | W32: 9층 | X32: 901 | Y32: 902 | Z32: 903 | AA32: 904 | AB32: 904 | AC32: 905 | AF32: 9층 | AG32: 901 | AH32: 902 | AI32: 903 | AJ32: 904 | AM32: 9층 | AN32: 901 | AO32: 902 | AP32: 903 | AQ32: 904 | AT32: 9층 | AU32: 901 | AV32: 902 | AW32: 903 | AX32: 904 | BA32: 9층 | BB32: 901 | BC32: 902 | BD32: 903 | BE32: 904 | BH32: 9층 | BI32: 901 | BJ32: 902 | BK32: 903 | BL32: 904 | BO32: 9층 | BP32: 901 | BQ32: 902 | BR32: 903 | BS32: 904
